Workbook

Sheet Sheet2
A3: Row Labels | B3: Sum of Total
A4: Shea | B4: 40
A5: Tim | B5: 33
A6: Sonat | B6: 32
A7: Lindsay | B7: 27
A8: Cody | B8: 26
A9: Jeremy | B9: 23
A10: Lance | B10: 19
A11: Jordan | B11: 15
A12: Grand Total | B12: 215

Sheet Leaderboard 2026
A1: Player | B1: Sum of Total
A2: Shea | B2: 89.5
A3: Cody | B3: 87
A4: Michael | B4: 81
A5: Tim | B5: 77
A6: Jeremy | B6: 71.5
A7: Lance | B7: 66.5
A8: Sonat | B8: 66.5
A9: Lindsay | B9: 37
A10: Grand Total | B10: 576
A12: Tournament 1 | P12: Closest Too
A13: Player | B13: Week 1 | C13: Points | D13: Week 2 | E13: Points | F13: Week 3 | G13: Points | H13: Week 4 | I13: Points | J13: Week 5 | K13: Points | L13: Week 6 | M13: Points | N13: Total | P13: Player | Q13: Total | R13: Week 1 | S13: Week 2 | T13: Week 3 | U13: Week 4 | V13: Week 5 | W13: Week 6 | X13: Week 7 | Y13: Week 8 | Z13: Week 9 | AA13: Week 10 | AB13: Week 11 | AC13: Week 12 | AD13: Week 13 | AE13: Week 14 | AF13: Week 15 | AG13: Week 16 | AH13: Week 17 | AI13: Week 18
A14: Cody | B14: 37 | C14: 5 | D14: 39 | E14: 4 | F14: 40 | G14: 5 | H14: 45 | I14: 3 | J14: 35 | K14: 6 | L14: 38 | M14: 5 | N14: 28 | P14: Cody | Q14: 1 | R14: - | S14: - | T14: - | U14: - | V14: - | W14: 2.9 | X14: - | Y14: - | Z14: - | AA14: - | AB14: - | AC14: -
A15: Jeremy | B15: 49.5 | C15: 1 | D15: 40.5 | E15: 2 | F15: 47.5 | G15: 2 | H15: 42.5 | I15: 5 | J15: 40.5 | K15: 3 | L15: 47.5 | M15: 2 | N15: 15 | P15: Jeremy | Q15: 2 | R15: 9.5 | S15: - | T15: - | U15: - | V15: - | W15: - | X15: 14.8 | Y15: 13.6 | Z15: - | AA15: - | AB15: - | AC15: -
A16: Lance | B16: 32 | C16: 8 | D16: 50 | E16: 1 | F16: 44 | G16: 4 | H16: 49 | I16: 2 | J16: 38 | K16: 5 | L16: 42 | M16: 3.5 | N16: 23.5 | P16: Lance | Q16: 0 | R16: 7.9 | S16: - | T16: - | U16: - | V16: - | W16: - | X16: - | Y16: - | Z16: - | AA16: - | AB16: - | AC16: -
A17: Shea | B17: 36.5 | C17: 6 | D17: 34.5 | E17: 8 | F17: 31.5 | G17: 8 | H17: 35.5 | I17: 8 | J17: 34.5 | K17: 7 | L17: 36.5 | M17: 6 | N17: 43 | P17: Shea | Q17: 2 | R17: 3.5 | S17: - | T17: - | U17: - | V17: 6.6 | W17: - | X17: - | Y17: - | Z17: - | AA17: - | AB17: - | AC17: 3.1
A18: Michael | B18: 38 | C18: 3.5 | D18: 37 | E18: 5 | F18: 38 | G18: 7 | H18: 39 | I18: 6 | J18: 41 | K18: 2 | L18: 42 | M18: 3.5 | N18: 27 | P18: Michael | Q18: 2 | R18: - | S18: - | T18: - | U18: 14.8 | V18: - | W18: 6.3 | X18: - | Y18: - | Z18: 5 | AA18: - | AB18: - | AC18: -
A19: Tim | B19: 39.5 | C19: 2 | D19: 35.5 | E19: 7 | F19: 39.5 | G19: 6 | H19: 37.5 | I19: 7 | J19: 38.5 | K19: 4 | L19: 35.5 | M19: 7 | N19: 33 | P19: Tim | Q19: 2 | R19: - | S19: 9.9 | T19: 8.5 | U19: - | V19: - | W19: - | X19: - | Y19: - | Z19: - | AA19: - | AB19: 4.8 | AC19: -
A20: Sonat | B20: 38 | C20: 3.5 | D20: 40 | E20: 3 | F20: 46 | G20: 3 | H20: 43 | I20: 4 | J20: 34 | K20: 8 | L20: 34 | M20: 8 | N20: 29.5 | P20: Sonat | Q20: 2 | R20: 10.2 | S20: - | T20: 11.5 | U20: 14.8 | V20: 2.9 | W20: - | X20: - | Y20: - | Z20: - | AA20: 6.6 | AB20: 4.9 | AC20: -
A21: Lindsay | B21: 36 | C21: 7 | D21: 36 | E21: 6 | F21: -4 | G21: 1 | H21: -4 | I21: 1 | J21: -4 | K21: 1 | L21: -4 | M21: 1 | N21: 17 | P21: Lindsay | Q21: 1 | R21: 17.4 | S21: 1.7 | T21: - | U21: - | V21: - | W21: 9.3 | X21: - | Y21: - | Z21: - | AA21: - | AB21: - | AC21: -
A23: Tournament 2
A24: Player | B24: Week 1 | C24: Points | D24: Week 2 | E24: Points | F24: Week 3 | G24: Points | H24: Week 4 | I24: Points | J24: Week 5 | K24: Points | L24: Week 6 | M24: Points | N24: Total
A25: Cody | B25: 38 | C25: 3 | D25: 35 | E25: 6 | F25: 34 | G25: 6 | H25: 32 | I25: 6 | J25: 36 | K25: 4 | L25: 19 | M25: 8 | N25: 33
A26: Jeremy | B26: 35 | C26: 6.5 | D26: 37 | E26: 5 | F26: 35 | G26: 5 | H26: 36 | I26: 4 | J26: 31 | K26: 8 | L26: 29 | M26: 5.5 | N26: 34
A27: Lance | B27: 32.125 | C27: 8 | D27: 40.125 | E27: 2.5 | F27: 39 | G27: 2 | H27: 41 | I27: 2 | J27: 37 | K27: 2.5 | L27: 26 | M27: 7 | N27: 24
A28: Shea | B28: 36.375 | C28: 4.5 | D28: 33.375 | E28: 8 | F28: 37 | G28: 3.5 | H28: 30 | I28: 8 | J28: 35 | K28: 5 | L28: 33 | M28: 3 | N28: 32
A29: Michael | B29: 34.625 | C29: 6.5 | D29: 39.625 | E29: 2.5 | F29: 30 | G29: 8 | H29: 33 | I29: 5 | J29: 32 | K29: 7 | L29: 29 | M29: 5.5 | N29: 34.5
A30: Tim | B30: 39.25 | C30: 2 | D30: 34.25 | E30: 7 | F30: 32 | G30: 7 | H30: 37 | I30: 3 | J30: 34 | K30: 6 | L30: 36 | M30: 2 | N30: 27
A31: Sonat | B31: 35.625 | C31: 4.5 | D31: 38.625 | E31: 4 | F31: 37 | G31: 3.5 | H31: 31 | I31: 7 | J31: 37 | K31: 2.5 | L31: 30 | M31: 4 | N31: 25.5
A32: Lindsay | B32: -4 | C32: 1 | D32: -4 | E32: 1 | F32: -4 | G32: 1 | H32: -4 | I32: 1 | J32: 38 | K32: 1 | L32: -4 | M32: 1 | N32: 6
A34: Tournament 3
A35: Player | B35: Week 1 | C35: Points | D35: Week 2 | E35: Points | F35: Week 3 | G35: Points | H35: Week 4 | I35: Points | J35: Week 5 | K35: Points | L35: Week 6 | M35: Points | N35: Total
A36: Cody | B36: 38 | C36: 6 | D36: 34 | E36: 7 | F36: 38 | G36: 5.5 | H36: =Y61 -> 0 | I36: 7.5 | N36: =C36+E36+G36+I36+K36+M36 -> 26
A37: Jeremy | B37: 38 | C37: 6 | D37: 39 | E37: 4 | F37: 35 | G37: 7 | H37: =Y62 -> 0 | I37: 5.5 | N37: =C37+E37+G37+I37+K37+M37 -> 22.5
A38: Lance | B38: 36 | C38: 8 | D38: 41 | E38: 1 | F38: 34 | G38: 8 | H38: =Y63 -> 0 | I38: 2 | N38: =C38+E38+G38+I38+K38+M38 -> 19
A39: Shea | B39: 48 | C39: 2 | D39: 36 | E39: 6 | F39: 38 | G39: 5.5 | H39: =Y64 -> 0 | I39: 1 | N39: =C39+E39+G39+I39+K39+M39 -> 14.5
A40: Michael | B40: 38 | C40: 6 | D40: 37 | E40: 5 | F40: 39 | G40: 3 | H40: =Y65 -> 0 | I40: 5.5 | N40: =C40+E40+G40+I40+K40+M40 -> 19.5
A41: Tim | B41: 42 | C41: 4 | D41: 33 | E41: 8 | F41: 40 | G41: 1 | H41: =Y66 -> 0 | I41: 4 | N41: =C41+E41+G41+I41+K41+M41 -> 17
A42: Sonat | B42: 45 | C42: 3 | D42: 40 | E42: 2.5 | F42: 39 | G42: 3 | H42: =Y67 -> 0 | I42: 3 | N42: =C42+E42+G42+I42+K42+M42 -> 11.5
A43: Lindsay | B43: -5 | C43: 1 | D43: 40 | E43: 2.5 | F43: 39 | G43: 3 | H43: =Y68 -> 0 | I43: 7.5 | N43: =C43+E43+G43+I43+K43+M43 -> 14

Sheet Tournament 3 (2026)
A1: Player | B1: Sum of Total
A2: Cody | B2: 26
A3: Jeremy | B3: 22.5
A4: Michael | B4: 19.5
A5: Lance | B5: 19
A6: Tim | B6: 17
A7: Shea | B7: 14.5
A8: Lindsay | B8: 14
A9: Sonat | B9: 11.5
A10: Grand Total | B10: 144
U11: *
A12: Tournament 3 | P12: Points | R12: *split points if tied* | T12: Closest Too
A13: Player | B13: Week 1 | C13: Points | D13: Week 2 | E13: Points | F13: Week 3 | G13: Points | H13: Week 4 | I13: Points | J13: Week 5 | K13: Points | L13: Week 6 | M13: Points | N13: Total | P13: 1st | Q13: 8 | T13: Player | U13: Week 1 | V13: Week 2 | W13: Week 3 | X13: Week 4 | Y13: Week 5 | Z13: Week 6
A14: Cody | B14: =M26 -> 38 | C14: 6 | D14: =Y26 -> 34 | E14: 7 | F14: =M39 -> 38 | G14: 5.5 | H14: =Y39 -> 31 | I14: 7.5 | J14: =M52 -> -21 | L14: =Y52 -> -21 | N14: =C14+E14+G14+I14+K14+M14 -> 26 | P14: 2nd | Q14: 7 | T14: Cody | U14: - | W14: - | X14: -
A15: Jeremy | B15: =M27 -> 38 | C15: 6 | D15: =Y27 -> 39 | E15: 4 | F15: =M40 -> 35 | G15: 7 | H15: =Y40 -> 32 | I15: 5.5 | J15: =M53 -> -20 | L15: =Y53 -> -20 | N15: =C15+E15+G15+I15+K15+M15 -> 22.5 | P15: 3rd | Q15: 6 | T15: Jeremy | U15: - | W15: - | X15: 16.4
A16: Lance | B16: =M28 -> 36 | C16: 8 | D16: =Y28 -> 41 | E16: 1 | F16: =M41 -> 34 | G16: 8 | H16: =Y41 -> 43 | I16: 2 | J16: =M54 -> -18 | L16: =Y54 -> -18 | N16: =C16+E16+G16+I16+K16+M16 -> 19 | P16: 4th | Q16: 5 | T16: Lance | U16: - | W16: - | X16: -
A17: Shea | B17: =M29 -> 48 | C17: 2 | D17: =Y29 -> 36 | E17: 6 | F17: =M42 -> 38 | G17: 5.5 | H17: =Y42 -> 44 | I17: 1 | J17: =M55 -> -5 | L17: =Y55 -> -5 | N17: =C17+E17+G17+I17+K17+M17 -> 14.5 | P17: 5th | Q17: 4 | T17: Shea | U17: 7.1 | W17: - | X17: -
A18: Michael | B18: =M30 -> 38 | C18: 6 | D18: =Y30 -> 37 | E18: 5 | F18: =M43 -> 39 | G18: 3 | H18: =Y43 -> 32 | I18: 5.5 | J18: =M56 -> -7 | L18: =Y56 -> -7 | N18: =C18+E18+G18+I18+K18+M18 -> 19.5 | P18: 6th | Q18: 3 | T18: Michael | U18: - | W18: - | X18: 4.7
A19: Tim | B19: =M31 -> 42 | C19: 4 | D19: =Y31 -> 33 | E19: 8 | F19: =M44 -> 40 | G19: 1 | H19: =Y44 -> 34 | I19: 4 | J19: =M57 -> -7 | L19: =Y57 -> -7 | N19: =C19+E19+G19+I19+K19+M19 -> 17 | P19: 7th | Q19: 2 | T19: Tim | U19: - | W19: - | X19: 14.5
A20: Sonat | B20: =M32 -> 45 | C20: 3 | D20: =Y32 -> 40 | E20: 2.5 | F20: =M45 -> 39 | G20: 3 | H20: =Y45 -> 39 | I20: 3 | J20: =M58 -> -7 | L20: =Y58 -> -7 | N20: =C20+E20+G20+I20+K20+M20 -> 11.5 | P20: 8th | Q20: 1 | T20: Sonat | U20: - | W20: - | X20: -
A21: Lindsay | B21: =M33 -> -5 | C21: 1 | D21: =Y33 -> 40 | E21: 2.5 | F21: =M46 -> 39 | G21: 3 | H21: =Y46 -> 31 | I21: 7.5 | J21: =M59 -> -5 | L21: =Y59 -> -5 | N21: =C21+E21+G21+I21+K21+M21 -> 14 | T21: Lindsay | W21: - | X21: -
A23: Shadow Creek | B23: 1 | C23: 2 | D23: 3 | E23: 4 | F23: 5 | G23: 6 | H23: 7 | I23: 8 | J23: 9 | K23: Total | L23: Handicap | M23: Score | N23: 10 | O23: 11 | P23: 12 | Q23: 13 | R23: 14 | S23: 15 | T23: 16 | U23: 17 | V23: 18 | W23: Total | X23: Handicap | Y23: Score
A24: Par | B24: 4 | C24: 4 | D24: 4 | E24: 5 | F24: 3 | G24: 4 | H24: 5 | I24: 3 | J24: 4 | K24: =SUM(B24:J24) -> 36 | N24: 4 | O24: 4 | P24: 4 | Q24: 3 | R24: 4 | S24: 4 | T24: 5 | U24: 3 | V24: 5 | W24: =SUM(N24:V24) -> 36
A25: Player
A26: Cody | B26: 7 | C26: 5 | D26: 8 | E26: 7 | F26: 7 | G26: 6 | H26: 7 | I26: 5 | J26: 7 | K26: =SUM(B26:J26) -> 59 | L26: 21 | M26: =K26-L26 -> 38 | N26: 9 | O26: 5 | P26: 5 | Q26: 4 | R26: 5 | S26: 8 | T26: 9 | U26: 4 | V26: 6 | W26: =SUM(N26:V26) -> 55 | X26: 21 | Y26: =W26-X26 -> 34
A27: Jeremy | B27: 8 | C27: 7 | D27: 6 | E27: 8 | F27: 3 | G27: 8 | H27: 8 | I27: 4 | J27: 6 | K27: =SUM(B27:J27) -> 58 | L27: 20 | M27: =K27-L27 -> 38 | N27: 6 | O27: 5 | P27: 6 | Q27: 6 | R27: 6 | S27: 7 | T27: 8 | U27: 6 | V27: 9 | W27: =SUM(N27:V27) -> 59 | X27: 20 | Y27: =W27-X27 -> 39
A28: Lance | B28: 6 | C28: 5 | D28: 7 | E28: 9 | F28: 6 | G28: 7 | H28: 5 | I28: 4 | J28: 5 | K28: =SUM(B28:J28) -> 54 | L28: 18 | M28: =K28-L28 -> 36 | N28: 6 | O28: 6 | P28: 5 | Q28: 6 | R28: 10 | S28: 6 | T28: 8 | U28: 4 | V28: 8 | W28: =SUM(N28:V28) -> 59 | X28: 18 | Y28: =W28-X28 -> 41
A29: Shea | B29: 6 | C29: 5 | D29: 6 | E29: 8 | F29: 3 | G29: 5 | H29: 5 | I29: 8 | J29: 7 | K29: =SUM(B29:J29) -> 53 | L29: 5 | M29: =K29-L29 -> 48 | N29: 5 | O29: 3 | P29: 5 | Q29: 3 | R29: 5 | S29: 4 | T29: 7 | U29: 3 | V29: 6 | W29: =SUM(N29:V29) -> 41 | X29: 5 | Y29: =W29-X29 -> 36
A30: Michael | B30: 4 | C30: 5 | D30: 9 | E30: 6 | F30: 3 | G30: 5 | H30: 6 | I30: 3 | J30: 4 | K30: =SUM(B30:J30) -> 45 | L30: 7 | M30: =K30-L30 -> 38 | N30: 5 | O30: 5 | P30: 4 | Q30: 4 | R30: 5 | S30: 5 | T30: 6 | U30: 4 | V30: 6 | W30: =SUM(N30:V30) -> 44 | X30: 7 | Y30: =W30-X30 -> 37
A31: Tim | B31: 4 | C31: 6 | D31: 6 | E31: 6 | F31: 4 | G31: 6 | H31: 7 | I31: 5 | J31: 5 | K31: =SUM(B31:J31) -> 49 | L31: 7 | M31: =K31-L31 -> 42 | N31: 5 | O31: 4 | P31: 4 | Q31: 4 | R31: 4 | S31: 5 | T31: 7 | U31: 2 | V31: 5 | W31: =SUM(N31:V31) -> 40 | X31: 7 | Y31: =W31-X31 -> 33
A32: Sonat | B32: 6 | C32: 6 | D32: 6 | E32: 6 | F32: 4 | G32: 6 | H32: 6 | I32: 5 | J32: 7 | K32: =SUM(B32:J32) -> 52 | L32: 7 | M32: =K32-L32 -> 45 | N32: 5 | O32: 4 | P32: 4 | Q32: 5 | R32: 7 | S32: 5 | T32: 5 | U32: 5 | V32: 7 | W32: =SUM(N32:V32) -> 47 | X32: 7 | Y32: =W32-X32 -> 40
A33: Lindsay | K33: =SUM(B33:J33) -> 0 | L33: 5 | M33: =K33-L33 -> -5 | N33: 5 | O33: 7 | P33: 3 | Q33: 4 | R33: 5 | S33: 5 | T33: 7 | U33: 3 | V33: 6 | W33: =SUM(N33:V33) -> 45 | X33: 5 | Y33: =W33-X33 -> 40
F34: 140 yrd | I34: 160 yrd | Q34: 202 yrd | U34: 140 yrd
A36: Greystone | B36: 1 | C36: 2 | D36: 3 | E36: 4 | F36: 5 | G36: 6 | H36: 7 | I36: 8 | J36: 9 | K36: Total | L36: Handicap | M36: Score | N36: 10 | O36: 11 | P36: 12 | Q36: 13 | R36: 14 | S36: 15 | T36: 16 | U36: 17 | V36: 18 | W36: Total | X36: Handicap | Y36: Score
A37: Par | B37: 5 | C37: 3 | D37: 4 | E37: 5 | F37: 4 | G37: 3 | H37: 4 | I37: 4 | J37: 4 | K37: =SUM(B37:J37) -> 36 | N37: 5 | O37: 3 | P37: 4 | Q37: 4 | R37: 3 | S37: 4 | T37: 4 | U37: 4 | V37: 5 | W37: =SUM(N37:V37) -> 36
A38: Player
A39: Cody | B39: 7 | C39: 6 | D39: 8 | E39: 9 | F39: 5 | G39: 5 | H39: 8 | I39: 4 | J39: 7 | K39: =SUM(B39:J39) -> 59 | L39: 21 | M39: =K39-L39 -> 38 | N39: 6 | O39: 4 | P39: 6 | Q39: 6 | R39: 5 | S39: 4 | T39: 8 | U39: 6 | V39: 7 | W39: =SUM(N39:V39) -> 52 | X39: 21 | Y39: =W39-X39 -> 31
A40: Jeremy | B40: 5 | C40: 6 | D40: 6 | E40: 9 | F40: 6 | G40: 5 | H40: 6 | I40: 6 | J40: 6 | K40: =SUM(B40:J40) -> 55 | L40: 20 | M40: =K40-L40 -> 35 | N40: 9 | O40: 4 | P40: 7 | Q40: 7 | R40: 3 | S40: 5 | T40: 6 | U40: 6 | V40: 5 | W40: =SUM(N40:V40) -> 52 | X40: 20 | Y40: =W40-X40 -> 32
A41: Lance | B41: 6 | C41: 5 | D41: 7 | E41: 5 | F41: 8 | G41: 4 | H41: 7 | I41: 6 | J41: 4 | K41: =SUM(B41:J41) -> 52 | L41: 18 | M41: =K41-L41 -> 34 | N41: 14 | O41: 4 | P41: 6 | Q41: 9 | R41: 4 | S41: 5 | T41: 6 | U41: 6 | V41: 7 | W41: =SUM(N41:V41) -> 61 | X41: 18 | Y41: =W41-X41 -> 43
A42: Shea | B42: 6 | C42: 4 | D42: 4 | E42: 6 | F42: 5 | G42: 4 | H42: 5 | I42: 5 | J42: 4 | K42: =SUM(B42:J42) -> 43 | L42: 5 | M42: =K42-L42 -> 38 | N42: 5 | O42: 4 | P42: 7 | Q42: 4 | R42: 5 | S42: 5 | T42: 4 | U42: 9 | V42: 6 | W42: =SUM(N42:V42) -> 49 | X42: 5 | Y42: =W42-X42 -> 44
...

Sheet Tournament 2 (2026)
A1: Player | B1: Sum of Total
A2: Michael | B2: 34.5
A3: Jeremy | B3: 34
A4: Cody | B4: 33
A5: Shea | B5: 32
A6: Tim | B6: 27
A7: Sonat | B7: 25.5
A8: Lance | B8: 24
A9: Lindsay | B9: 6
A10: Grand Total | B10: 216
U11: *
A12: Tournament 2 | P12: Points | R12: *split points if tied* | T12: Closest Too
A13: Player | B13: Week 1 | C13: Points | D13: Week 2 | E13: Points | F13: Week 3 | G13: Points | H13: Week 4 | I13: Points | J13: Week 5 | K13: Points | L13: Week 6 | M13: Points | N13: Total | P13: 1st | Q13: 8 | T13: Player | U13: Week 1 | V13: Week 2 | W13: Week 3 | X13: Week 4 | Y13: Week 5 | Z13: Week 6
A14: Cody | B14: =M26 -> 38 | C14: 3 | D14: =Y26 -> 35 | E14: 6 | F14: =M39 -> 34 | G14: 6 | H14: =Y39 -> 32 | I14: 6 | J14: =M52 -> 36 | K14: 4 | L14: =Y52 -> 19 | M14: 8 | N14: =C14+E14+G14+I14+K14+M14 -> 33 | P14: 2nd | Q14: 7 | T14: Cody | U14: - | V14: - | W14: - | X14: - | Y14: - | Z14: -
A15: Jeremy | B15: =M27 -> 35 | C15: 6.5 | D15: =Y27 -> 37 | E15: 5 | F15: =M40 -> 35 | G15: 5 | H15: =Y40 -> 36 | I15: 4 | J15: =M53 -> 31 | K15: 8 | L15: =Y53 -> 29 | M15: 5.5 | N15: =C15+E15+G15+I15+K15+M15 -> 34 | P15: 3rd | Q15: 6 | T15: Jeremy | U15: 14.8 | V15: 13.6 | W15: - | X15: - | Y15: - | Z15: -
A16: Lance | B16: =M28 -> 32.125 | C16: 8 | D16: =Y28 -> 40.125 | E16: 2.5 | F16: =M41 -> 39 | G16: 2 | H16: =Y41 -> 41 | I16: 2 | J16: =M54 -> 37 | K16: 2.5 | L16: =Y54 -> 26 | M16: 7 | N16: =C16+E16+G16+I16+K16+M16 -> 24 | P16: 4th | Q16: 5 | T16: Lance | U16: - | V16: - | W16: - | X16: - | Y16: - | Z16: -
A17: Shea | B17: =M29 -> 36.375 | C17: 4.5 | D17: =Y29 -> 33.375 | E17: 8 | F17: =M42 -> 37 | G17: 3.5 | H17: =Y42 -> 30 | I17: 8 | J17: =M55 -> 35 | K17: 5 | L17: =Y55 -> 33 | M17: 3 | N17: =C17+E17+G17+I17+K17+M17 -> 32 | P17: 5th | Q17: 4 | T17: Shea | U17: - | V17: - | W17: - | X17: - | Y17: - | Z17: 3.1
A18: Michael | B18: =M30 -> 34.625 | C18: 6.5 | D18: =Y30 -> 39.625 | E18: 2.5 | F18: =M43 -> 30 | G18: 8 | H18: =Y43 -> 33 | I18: 5 | J18: =M56 -> 32 | K18: 7 | L18: =Y56 -> 29 | M18: 5.5 | N18: =C18+E18+G18+I18+K18+M18 -> 34.5 | P18: 6th | Q18: 3 | T18: Michael | U18: - | V18: - | W18: 5 | X18: - | Y18: - | Z18: -
A19: Tim | B19: =M31 -> 39.25 | C19: 2 | D19: =Y31 -> 34.25 | E19: 7 | F19: =M44 -> 32 | G19: 7 | H19: =Y44 -> 37 | I19: 3 | J19: =M57 -> 34 | K19: 6 | L19: =Y57 -> 36 | M19: 2 | N19: =C19+E19+G19+I19+K19+M19 -> 27 | P19: 7th | Q19: 2 | T19: Tim | U19: - | V19: - | W19: - | X19: - | Y19: 4.8 | Z19: -
A20: Sonat | B20: =M32 -> 35.625 | C20: 4.5 | D20: =Y32 -> 38.625 | E20: 4 | F20: =M45 -> 37 | G20: 3.5 | H20: =Y45 -> 31 | I20: 7 | J20: =M58 -> 37 | K20: 2.5 | L20: =Y58 -> 30 | M20: 4 | N20: =C20+E20+G20+I20+K20+M20 -> 25.5 | P20: 8th | Q20: 1 | T20: Sonat | U20: - | V20: - | W20: - | X20: 6.6 | Y20: 4.9 | Z20: -
A21: Lindsay | B21: =M33 -> -4 | C21: 1 | D21: =Y33 -> -4 | E21: 1 | F21: =M46 -> -4 | G21: 1 | H21: =Y46 -> -4 | I21: 1 | J21: =M59 -> 38 | K21: 1 | L21: =Y59 -> -4 | M21: 1 | N21: =C21+E21+G21+I21+K21+M21 -> 6 | T21: Lindsay | U21: - | V21: - | W21: - | X21: - | Y21: - | Z21: -
A23: TPC Scottdale | B23: 1 | C23: 2 | D23: 3 | E23: 4 | F23: 5 | G23: 6 | H23: 7 | I23: 8 | J23: 9 | K23: Total | L23: Handicap | M23: Score | N23: 10 | O23: 11 | P23: 12 | Q23: 13 | R23: 14 | S23: 15 | T23: 16 | U23: 17 | V23: 18 | W23: Total | X23: Handicap | Y23: Score
A24: Par | B24: 4 | C24: 4 | D24: 5 | E24: 3 | F24: 4 | G24: 4 | H24: 3 | I24: 4 | J24: 4 | K24: =SUM(B24:J24) -> 35 | N24: 4 | O24: 4 | P24: 3 | Q24: 5 | R24: 4 | S24: 5 | T24: 3 | U24: 4 | V24: 4 | W24: =SUM(N24:V24) -> 36
A25: Player
A26: Cody | B26: 9 | C26: 6 | D26: 8 | E26: 5 | F26: 7 | G26: 8 | H26: 4 | I26: 7 | J26: 6 | K26: =SUM(B26:J26) -> 60 | L26: 22 | M26: =K26-L26 -> 38 | N26: 6 | O26: 7 | P26: 4 | Q26: 8 | R26: 8 | S26: 6 | T26: 5 | U26: 6 | V26: 7 | W26: =SUM(N26:V26) -> 57 | X26: 22 | Y26: =W26-X26 -> 35
A27: Jeremy | B27: 6 | C27: 8 | D27: 6 | E27: 4 | F27: 6 | G27: 9 | H27: 3 | I27: 9 | J27: 4 | K27: =SUM(B27:J27) -> 55 | L27: 20 | M27: =K27-L27 -> 35 | N27: 8 | O27: 7 | P27: 7 | Q27: 7 | R27: 7 | S27: 5 | T27: 3 | U27: 5 | V27: 8 | W27: =SUM(N27:V27) -> 57 | X27: 20 | Y27: =W27-X27 -> 37
A28: Lance | B28: 5 | C28: 5 | D28: 6 | E28: 4 | F28: 8 | G28: 7 | H28: 4 | I28: 5 | J28: 6 | K28: =SUM(B28:J28) -> 50 | L28: 17.875 | M28: =K28-L28 -> 32.125 | N28: 5 | O28: 13 | P28: 6 | Q28: 7 | R28: 7 | S28: 7 | T28: 3 | U28: 6 | V28: 4 | W28: =SUM(N28:V28) -> 58 | X28: 17.875 | Y28: =W28-X28 -> 40.125
A29: Shea | B29: 5 | C29: 6 | D29: 8 | E29: 3 | F29: 4 | G29: 4 | H29: 4 | I29: 4 | J29: 4 | K29: =SUM(B29:J29) -> 42 | L29: 5.625 | M29: =K29-L29 -> 36.375 | N29: 4 | O29: 5 | P29: 3 | Q29: 5 | R29: 5 | S29: 5 | T29: 3 | U29: 4 | V29: 5 | W29: =SUM(N29:V29) -> 39 | X29: 5.625 | Y29: =W29-X29 -> 33.375
A30: Michael | B30: 6 | C30: 4 | D30: 6 | E30: 3 | F30: 5 | G30: 5 | H30: 3 | I30: 6 | J30: 5 | K30: =SUM(B30:J30) -> 43 | L30: 8.375 | M30: =K30-L30 -> 34.625 | N30: 5 | O30: 6 | P30: 3 | Q30: 5 | R30: 6 | S30: 7 | T30: 4 | U30: 6 | V30: 6 | W30: =SUM(N30:V30) -> 48 | X30: 8.375 | Y30: =W30-X30 -> 39.625
A31: Tim | B31: 5 | C31: 7 | D31: 5 | E31: 3 | F31: 8 | G31: 5 | H31: 4 | I31: 5 | J31: 4 | K31: =SUM(B31:J31) -> 46 | L31: 6.75 | M31: =K31-L31 -> 39.25 | N31: 5 | O31: 6 | P31: 3 | Q31: 5 | R31: 5 | S31: 6 | T31: 3 | U31: 4 | V31: 4 | W31: =SUM(N31:V31) -> 41 | X31: 6.75 | Y31: =W31-X31 -> 34.25
A32: Sonat | B32: 4 | C32: 6 | D32: 6 | E32: 4 | F32: 4 | G32: 5 | H32: 4 | I32: 6 | J32: 4 | K32: =SUM(B32:J32) -> 43 | L32: 7.375 | M32: =K32-L32 -> 35.625 | N32: 4 | O32: 6 | P32: 5 | Q32: 6 | R32: 5 | S32: 7 | T32: 3 | U32: 4 | V32: 6 | W32: =SUM(N32:V32) -> 46 | X32: 7.375 | Y32: =W32-X32 -> 38.625
A33: Lindsay | K33: =SUM(B33:J33) -> 0 | L33: 4 | M33: =K33-L33 -> -4 | W33: =SUM(N33:V33) -> 0 | X33: 4 | Y33: =W33-X33 -> -4
E34: 147 yrd | T34: 114 yrd
A36: Bigwin | B36: 1 | C36: 2 | D36: 3 | E36: 4 | F36: 5 | G36: 6 | H36: 7 | I36: 8 | J36: 9 | K36: Total | L36: Handicap | M36: Score | N36: 10 | O36: 11 | P36: 12 | Q36: 13 | R36: 14 | S36: 15 | T36: 16 | U36: 17 | V36: 18 | W36: Total | X36: Handicap | Y36: Score
A37: Par | B37: 4 | C37: 3 | D37: 5 | E37: 3 | F37: 4 | G37: 4 | H37: 5 | I37: 4 | J37: 4 | K37: =SUM(B37:J37) -> 36 | N37: 4 | O37: 4 | P37: 3 | Q37: 4 | R37: 4 | S37: 5 | T37: 4 | U37: 3 | V37: 5 | W37: =SUM(N37:V37) -> 36
A38: Player
A39: Cody | B39: 5 | C39: 5 | D39: 6 | E39: 4 | F39: 8 | G39: 6 | H39: 8 | I39: 8 | J39: 6 | K39: =SUM(B39:J39) -> 56 | L39: 22 | M39: =K39-L39 -> 34 | N39: 7 | O39: 7 | P39: 4 | Q39: 6 | R39: 4 | S39: 8 | T39: 7 | U39: 4 | V39: 7 | W39: =SUM(N39:V39) -> 54 | X39: 22 | Y39: =W39-X39 -> 32
A40: Jeremy | B40: 8 | C40: 7 | D40: 5 | E40: 4 | F40: 6 | G40: 6 | H40: 7 | I40: 6 | J40: 6 | K40: =SUM(B40:J40) -> 55 | L40: 20 | M40: =K40-L40 -> 35 | N40: 7 | O40: 7 | P40: 5 | Q40: 5 | R40: 6 | S40: 7 | T40: 7 | U40: 5 | V40: 7 | W40: =SUM(N40:V40) -> 56 | X40: 20 | Y40: =W40-X40 -> 36
A41: Lance | B41: 6 | C41: 4 | D41: 8 | E41: 4 | F41: 8 | G41: 6 | H41: 7 | I41: 6 | J41: 8 | K41: =SUM(B41:J41) -> 57 | L41: 18 | M41: =K41-L41 -> 39 | N41: 5 | O41: 10 | P41: 7 | Q41: 6 | R41: 7 | S41: 8 | T41: 5 | U41: 4 | V41: 7 | W41: =SUM(N41:V41) -> 59 | X41: 18 | Y41: =W41-X41 -> 41
A42: Shea | B42: 5 | C42: 3 | D42: 6 | E42: 4 | F42: 5 | G42: 5 | H42: 6 | I42: 4 | J42: 5 | K42: =SUM(B42:J42) -> 43 | L42: 6 | M42: =K42-L42 -> 37 | N42: 4 | O42: 5 | P42: 3 | Q42: 4 | R42: 4 | S42: 4 | T42: 4 | U42: 4 | V42: 4 | W42: =SUM(N42:V42) -> 36 | X42: 6 | Y42: =W42-X42 -> 30
...

Sheet Tournament 1 (2026)
A1: Player | B1: Sum of Total
A2: Shea | B2: 43
A3: Tim | B3: 33
A4: Sonat | B4: 29.5
A5: Cody | B5: 28
A6: Michael | B6: 27
A7: Lance | B7: 23.5
A8: Lindsay | B8: 17
A9: Jeremy | B9: 15
A10: Grand Total | B10: 216
A12: Tournament 1 | P12: Points | R12: *split points if tied* | T12: Closest Too
A13: Player | B13: Week 1 | C13: Points | D13: Week 2 | E13: Points | F13: Week 3 | G13: Points | H13: Week 4 | I13: Points | J13: Week 5 | K13: Points | L13: Week 6 | M13: Points | N13: Total | P13: 1st | Q13: 8 | T13: Player | U13: Week 1 | V13: Week 2 | W13: Week 3 | X13: Week 4 | Y13: Week 5 | Z13: Week 6
A14: Cody | B14: =M26 -> 37 | C14: 5 | D14: =Y26 -> 39 | E14: 4 | F14: =M39 -> 40 | G14: 5 | H14: =Y39 -> 45 | I14: 3 | J14: =M52 -> 35 | K14: 6 | L14: =Y52 -> 38 | M14: 5 | N14: =C14+E14+G14+I14+K14+M14 -> 28 | P14: 2nd | Q14: 7 | T14: Cody | U14: - | V14: - | W14: - | X14: - | Y14: - | Z14: 2.9
A15: Jeremy | B15: =M27 -> 49.5 | C15: 1 | D15: =Y27 -> 40.5 | E15: 2 | F15: =M40 -> 47.5 | G15: 2 | H15: =Y40 -> 42.5 | I15: 5 | J15: =M53 -> 40.5 | K15: 3 | L15: =Y53 -> 47.5 | M15: 2 | N15: =C15+E15+G15+I15+K15+M15 -> 15 | P15: 3rd | Q15: 6 | T15: Jeremy | U15: 9.5 | V15: - | W15: - | X15: - | Y15: - | Z15: -
A16: Lance | B16: =M28 -> 32 | C16: 8 | D16: =Y28 -> 50 | E16: 1 | F16: =M41 -> 44 | G16: 4 | H16: =Y41 -> 49 | I16: 2 | J16: =M54 -> 38 | K16: 5 | L16: =Y54 -> 42 | M16: 3.5 | N16: =C16+E16+G16+I16+K16+M16 -> 23.5 | P16: 4th | Q16: 5 | T16: Lance | U16: 7.9 | V16: - | W16: - | X16: - | Y16: - | Z16: -
A17: Shea | B17: =M29 -> 36.5 | C17: 6 | D17: =Y29 -> 34.5 | E17: 8 | F17: =M42 -> 31.5 | G17: 8 | H17: =Y42 -> 35.5 | I17: 8 | J17: =M55 -> 34.5 | K17: 7 | L17: =Y55 -> 36.5 | M17: 6 | N17: =C17+E17+G17+I17+K17+M17 -> 43 | P17: 5th | Q17: 4 | T17: Shea | U17: 3.5 | V17: - | W17: - | X17: - | Y17: 6.6 | Z17: -
A18: Michael | B18: =M30 -> 38 | C18: 3.5 | D18: =Y30 -> 37 | E18: 5 | F18: =M43 -> 38 | G18: 7 | H18: =Y43 -> 39 | I18: 6 | J18: =M56 -> 41 | K18: 2 | L18: =Y56 -> 42 | M18: 3.5 | N18: =C18+E18+G18+I18+K18+M18 -> 27 | P18: 6th | Q18: 3 | T18: Michael | U18: - | V18: - | W18: - | X18: 14.8 | Y18: - | Z18: 6.3
A19: Tim | B19: =M31 -> 39.5 | C19: 2 | D19: =Y31 -> 35.5 | E19: 7 | F19: =M44 -> 39.5 | G19: 6 | H19: =Y44 -> 37.5 | I19: 7 | J19: =M57 -> 38.5 | K19: 4 | L19: =Y57 -> 35.5 | M19: 7 | N19: =C19+E19+G19+I19+K19+M19 -> 33 | P19: 7th | Q19: 2 | T19: Tim | U19: - | V19: 9.9 | W19: 8.5 | X19: - | Y19: - | Z19: -
A20: Sonat | B20: =M32 -> 38 | C20: 3.5 | D20: =Y32 -> 40 | E20: 3 | F20: =M45 -> 46 | G20: 3 | H20: =Y45 -> 43 | I20: 4 | J20: =M58 -> 34 | K20: 8 | L20: =Y58 -> 34 | M20: 8 | N20: =C20+E20+G20+I20+K20+M20 -> 29.5 | P20: 8th | Q20: 1 | T20: Sonat | U20: 10.2 | V20: - | W20: 11.5 | X20: 14.8 | Y20: 2.9 | Z20: -
A21: Lindsay | B21: =M33 -> 36 | C21: 7 | D21: =Y33 -> 36 | E21: 6 | F21: =M46 -> -4 | G21: 1 | H21: =Y46 -> -4 | I21: 1 | J21: =M59 -> -4 | K21: 1 | L21: =Y59 -> -4 | M21: 1 | N21: =C21+E21+G21+I21+K21+M21 -> 17 | T21: Lindsay | U21: 17.4 | V21: 1.7 | W21: - | X21: - | Y21: - | Z21: 9.3
A23: Cabot Cliff | B23: 1 | C23: 2 | D23: 3 | E23: 4 | F23: 5 | G23: 6 | H23: 7 | I23: 8 | J23: 9 | K23: Total | L23: Handicap | M23: Score | N23: 10 | O23: 11 | P23: 12 | Q23: 13 | R23: 14 | S23: 15 | T23: 16 | U23: 17 | V23: 18 | W23: Total | X23: Handicap | Y23: Score
A24: Par | B24: 5 | C24: 4 | D24: 4 | E24: 3 | F24: 4 | G24: 3 | H24: 5 | I24: 5 | J24: 3 | K24: =SUM(B24:J24) -> 36 | N24: 5 | O24: 4 | P24: 3 | Q24: 4 | R24: 3 | S24: 5 | T24: 3 | U24: 4 | V24: 5 | W24: =SUM(N24:V24) -> 36
A25: Player
A26: Cody | B26: 7 | C26: 5 | D26: 7 | E26: 4 | F26: 5 | G26: 7 | H26: 10 | I26: 7 | J26: 4 | K26: =SUM(B26:J26) -> 56 | L26: 19 | M26: =K26-L26 -> 37 | N26: 7 | O26: 4 | P26: 4 | Q26: 5 | R26: 4 | S26: 7 | T26: 6 | U26: 11 | V26: 10 | W26: =SUM(N26:V26) -> 58 | X26: 19 | Y26: =W26-X26 -> 39
A27: Jeremy | B27: 10 | C27: 6 | D27: 7 | E27: 5 | F27: 6 | G27: 5 | H27: 15 | I27: 6 | J27: 3 | K27: =SUM(B27:J27) -> 63 | L27: 13.5 | M27: =K27-L27 -> 49.5 | N27: 8 | O27: 6 | P27: 3 | Q27: 5 | R27: 4 | S27: 11 | T27: 4 | U27: 7 | V27: 6 | W27: =SUM(N27:V27) -> 54 | X27: 13.5 | Y27: =W27-X27 -> 40.5
A28: Lance | B28: 6 | C28: 4 | D28: 9 | E28: 3 | F28: 4 | G28: 3 | H28: 7 | I28: 6 | J28: 3 | K28: =SUM(B28:J28) -> 45 | L28: 13 | M28: =K28-L28 -> 32 | N28: 8 | O28: 5 | P28: 6 | Q28: 5 | R28: 5 | S28: 9 | T28: 7 | U28: 9 | V28: 9 | W28: =SUM(N28:V28) -> 63 | X28: 13 | Y28: =W28-X28 -> 50
A29: Shea | B29: 5 | C29: 5 | D29: 7 | E29: 3 | F29: 4 | G29: 4 | H29: 6 | I29: 6 | J29: 3 | K29: =SUM(B29:J29) -> 43 | L29: 6.5 | M29: =K29-L29 -> 36.5 | N29: 7 | O29: 5 | P29: 3 | Q29: 4 | R29: 3 | S29: 6 | T29: 3 | U29: 5 | V29: 5 | W29: =SUM(N29:V29) -> 41 | X29: 6.5 | Y29: =W29-X29 -> 34.5
A30: Michael | B30: 7 | C30: 5 | D30: 6 | E30: 3 | F30: 5 | G30: 3 | H30: 5 | I30: 7 | J30: 3 | K30: =SUM(B30:J30) -> 44 | L30: 6 | M30: =K30-L30 -> 38 | N30: 8 | O30: 5 | P30: 3 | Q30: 5 | R30: 3 | S30: 5 | T30: 3 | U30: 4 | V30: 7 | W30: =SUM(N30:V30) -> 43 | X30: 6 | Y30: =W30-X30 -> 37
A31: Tim | B31: 7 | C31: 6 | D31: 5 | E31: 3 | F31: 5 | G31: 3 | H31: 6 | I31: 6 | J31: 4 | K31: =SUM(B31:J31) -> 45 | L31: 5.5 | M31: =K31-L31 -> 39.5 | N31: 6 | O31: 4 | P31: 4 | Q31: 3 | R31: 4 | S31: 5 | T31: 4 | U31: 5 | V31: 6 | W31: =SUM(N31:V31) -> 41 | X31: 5.5 | Y31: =W31-X31 -> 35.5
A32: Sonat | B32: 8 | C32: 5 | D32: 5 | E32: 4 | F32: 4 | G32: 3 | H32: 6 | I32: 5 | J32: 3 | K32: =SUM(B32:J32) -> 43 | L32: 5 | M32: =K32-L32 -> 38 | N32: 5 | O32: 6 | P32: 5 | Q32: 4 | R32: 4 | S32: 5 | T32: 4 | U32: 4 | V32: 8 | W32: =SUM(N32:V32) -> 45 | X32: 5 | Y32: =W32-X32 -> 40
A33: Lindsay | B33: 5 | C33: 6 | D33: 5 | E33: 2 | F33: 4 | G33: 4 | H33: 6 | I33: 5 | J33: 3 | K33: =SUM(B33:J33) -> 40 | L33: 4 | M33: =K33-L33 -> 36 | N33: 5 | O33: 4 | P33: 4 | Q33: 4 | R33: 4 | S33: 6 | T33: 2 | U33: 5 | V33: 6 | W33: =SUM(N33:V33) -> 40 | X33: 4 | Y33: =W33-X33 -> 36
G34: 153 yrd | J34: 109 yrd | P34: 200 yrd | T34: 125 yrd
A36: Whispering Pines | B36: 1 | C36: 2 | D36: 3 | E36: 4 | F36: 5 | G36: 6 | H36: 7 | I36: 8 | J36: 9 | K36: Total | L36: Handicap | M36: Score | N36: 10 | O36: 11 | P36: 12 | Q36: 13 | R36: 14 | S36: 15 | T36: 16 | U36: 17 | V36: 18 | W36: Total | X36: Handicap | Y36: Score
A37: Par | B37: 4 | C37: 5 | D37: 3 | E37: 4 | F37: 3 | G37: 4 | H37: 4 | I37: 5 | J37: 4 | K37: =SUM(B37:J37) -> 36 | N37: 3 | O37: 4 | P37: 5 | Q37: 4 | R37: 3 | S37: 4 | T37: 5 | U37: 4 | V37: 4 | W37: =SUM(N37:V37) -> 36
A38: Player
A39: Cody | B39: 6 | C39: 8 | D39: 3 | E39: 8 | F39: 4 | G39: 7 | H39: 8 | I39: 9 | J39: 6 | K39: =SUM(B39:J39) -> 59 | L39: 19 | M39: =K39-L39 -> 40 | N39: 4 | O39: 6 | P39: 7 | Q39: 8 | R39: 7 | S39: 8 | T39: 9 | U39: 6 | V39: 9 | W39: =SUM(N39:V39) -> 64 | X39: 19 | Y39: =W39-X39 -> 45
A40: Jeremy | B40: 7 | C40: 15 | D40: 4 | E40: 8 | F40: 5 | G40: 4 | H40: 5 | I40: 8 | J40: 5 | K40: =SUM(B40:J40) -> 61 | L40: 13.5 | M40: =K40-L40 -> 47.5 | N40: 3 | O40: 8 | P40: 9 | Q40: 7 | R40: 5 | S40: 4 | T40: 8 | U40: 7 | V40: 5 | W40: =SUM(N40:V40) -> 56 | X40: 13.5 | Y40: =W40-X40 -> 42.5
A41: Lance | B41: 6 | C41: 7 | D41: 4 | E41: 8 | F41: 6 | G41: 6 | H41: 7 | I41: 5 | J41: 8 | K41: =SUM(B41:J41) -> 57 | L41: 13 | M41: =K41-L41 -> 44 | N41: 5 | O41: 5 | P41: 8 | Q41: 6 | R41: 6 | S41: 6 | T41: 9 | U41: 7 | V41: 10 | W41: =SUM(N41:V41) -> 62 | X41: 13 | Y41: =W41-X41 -> 49
A42: Shea | B42: 4 | C42: 4 | D42: 4 | E42: 5 | F42: 4 | G42: 4 | H42: 5 | I42: 4 | J42: 4 | K42: =SUM(B42:J42) -> 38 | L42: 6.5 | M42: =K42-L42 -> 31.5 | N42: 4 | O42: 5 | P42: 5 | Q42: 5 | R42: 4 | S42: 4 | T42: 6 | U42: 5 | V42: 4 | W42: =SUM(N42:V42) -> 42 | X42: 6.5 | Y42: =W42-X42 -> 35.5
A43: Michael | B43: 4 | C43: 7 | D43: 4 | E43: 5 | F43: 4 | G43: 6 | H43: 5 | I43: 5 | J43: 4 | K43: =SUM(B43:J43) -> 44 | L43: 6 | M43: =K43-L43 -> 38 | N43: 4 | O43: 6 | P43: 5 | Q43: 5 | R43: 4 | S43: 6 | T43: 5 | U43: 5 | V43: 5 | W43: =SUM(N43:V43) -> 45 | X43: 6 | Y43: =W43-X43 -> 39
...

Sheet Handicap Summary 2026
A1: Tournament 1 | H1: Player | I1: Handicap
A2: Player | B2: Week 1 | C2: Week 2 | D2: 2 Wk Ave | E2: Par 36 | H2: Cody | I2: 19
A3: Cody | B3: ='Wk1and2 2026'!K5 -> 55 | C3: ='Wk1and2 2026'!V5 -> 55 | D3: =(B3+C3)/2 -> 55 | E3: =D3-36 -> 19 | H3: Jeremy | I3: 13.5
A4: Jeremy | B4: ='Wk1and2 2026'!K19 -> 50 | C4: ='Wk1and2 2026'!V19 -> 49 | D4: =(B4+C4)/2 -> 49.5 | E4: =D4-36 -> 13.5 | H4: Lance | I4: 13
A5: Lance | B5: ='Wk1and2 2026'!K11 -> 50 | C5: ='Wk1and2 2026'!V11 -> 48 | D5: =(B5+C5)/2 -> 49 | E5: =D5-36 -> 13 | H5: Shea | I5: 6.5
A6: Shea | B6: ='Wk1and2 2026'!K13 -> 43 | C6: ='Wk1and2 2026'!V13 -> 42 | D6: =(B6+C6)/2 -> 42.5 | E6: =D6-36 -> 6.5 | H6: Michael | I6: 6
A7: Michael | B7: ='Wk1and2 2026'!K7 -> 44 | C7: ='Wk1and2 2026'!V7 -> 40 | D7: =(B7+C7)/2 -> 42 | E7: =D7-36 -> 6 | H7: Tim | I7: 5.5
A8: Tim | B8: ='Wk1and2 2026'!K15 -> 41 | C8: ='Wk1and2 2026'!V15 -> 42 | D8: =(B8+C8)/2 -> 41.5 | E8: =D8-36 -> 5.5 | H8: Sonat | I8: 5
A9: Sonat | B9: ='Wk1and2 2026'!K17 -> 43 | C9: ='Wk1and2 2026'!V17 -> 39 | D9: =(B9+C9)/2 -> 41 | E9: =D9-36 -> 5 | H9: Lindsay | I9: 4
A10: Lindsay | B10: ='Wk1and2 2026'!K9 -> 40 | C10: ='Wk1and2 2026'!V9 -> 40 | D10: =(B10+C10)/2 -> 40 | E10: =D10-36 -> 4

Sheet Total Prize Money Overall
A1: Overall | G1: 2026 | M1: 2025
A2: Player | B2: Tourney $ | C2: Closest Too | D2: Chip Ins | E2: Total | G2: Player | H2: Tourney $ | I2: Closest Too | J2: Chip Ins | K2: Total | M2: Player | N2: Tourney $ | O2: Closest Too | P2: Total
A3: Cody | B3: =H3+N3 -> 0 | C3: =I3+O3 -> 20 | E3: =SUM(B3:D3) -> 20 | G3: Cody | I3: 20 | K3: =SUM(H3:J3) -> 20 | M3: Cody | P3: =SUM(N3:O3) -> 0
A4: Michael | B4: =H4+N4 -> 200 | C4: =I4+O4 -> 40 | E4: =SUM(B4:D4) -> 240 | G4: Michael | H4: 200 | I4: 40 | K4: =SUM(H4:J4) -> 240 | M4: Michael | P4: =SUM(N4:O4) -> 0
A5: Lindsay | B5: =H5+N5 -> 0 | C5: =I5+O5 -> 100 | E5: =SUM(B5:D5) -> 100 | G5: Lindsay | I5: 20 | K5: =SUM(H5:J5) -> 20 | M5: Lindsay | O5: 80 | P5: =SUM(N5:O5) -> 80
A6: Lance | B6: =H6+N6 -> 0 | C6: =I6+O6 -> 0 | D6: 82 | E6: =SUM(B6:D6) -> 82 | G6: Lance | J6: 82 | K6: =SUM(H6:J6) -> 82 | M6: Lance | P6: =SUM(N6:O6) -> 0
A7: Shea | B7: =H7+N7 -> 600 | C7: =I7+O7 -> 220 | E7: =SUM(B7:D7) -> 820 | G7: Shea | H7: 200 | I7: 60 | K7: =SUM(H7:J7) -> 260 | M7: Shea | N7: 400 | O7: 160 | P7: =SUM(N7:O7) -> 560
A8: Tim | B8: =H8+N8 -> 150 | C8: =I8+O8 -> 120 | D8: 38 | E8: =SUM(B8:D8) -> 308 | G8: Tim | H8: 50 | I8: 80 | J8: 38 | K8: =SUM(H8:J8) -> 168 | M8: Tim | N8: 100 | O8: 40 | P8: =SUM(N8:O8) -> 140
A9: Sonat | B9: =H9+N9 -> 50 | C9: =I9+O9 -> 100 | D9: 16 | E9: =SUM(B9:D9) -> 166 | G9: Sonat | I9: 40 | J9: 16 | K9: =SUM(H9:J9) -> 56 | M9: Sonat | N9: 50 | O9: 60 | P9: =SUM(N9:O9) -> 110
A10: Jeremy | B10: =H10+N10 -> 250 | C10: =I10+O10 -> 40 | D10: 48.35 | E10: =SUM(B10:D10) -> 338.35 | G10: Jeremy | H10: 50 | I10: 40 | J10: 48.35 | K10: =SUM(H10:J10) -> 138.35 | M10: Jeremy | N10: 200 | P10: =SUM(N10:O10) -> 200
A11: Jordan | B11: =H11+N11 -> 0 | C11: =I11+O11 -> 20 | E11: =SUM(B11:D11) -> 20 | G11: Jordan | K11: =SUM(H11:J11) -> 0 | M11: Jordan | O11: 20 | P11: =SUM(N11:O11) -> 20
E12: =SUM(E3:E11) -> 2094.35 | K12: =SUM(K3:K11) -> 984.35 | P12: =SUM(P3:P11) -> 1110

Sheet Total Prize Money 2026
A2: Player | B2: Tourney $ | C2: Closest Too | D2: Chip Ins | E2: Total
A3: Cody | C3: 20 | E3: =SUM(B3:D3) -> 20
A4: Michael | B4: 200 | C4: 40 | E4: =SUM(B4:D4) -> 240
A5: Lindsay | C5: 20 | E5: =SUM(B5:D5) -> 20
A6: Lance | D6: 82 | E6: =SUM(B6:D6) -> 82
A7: Shea | B7: 200 | C7: 40 | E7: =SUM(B7:D7) -> 240
A8: Tim | B8: 70 | C8: 80 | D8: 38 | E8: =SUM(B8:D8) -> 188
A9: Sonat | C9: 40 | D9: 16 | E9: =SUM(B9:D9) -> 56
A10: Jeremy | B10: 50 | C10: 40 | D10: 84.35 | E10: =SUM(B10:D10) -> 174.35
A11: Jordan | E11: =SUM(B11:D11) -> 0
E12: =SUM(E3:E11) -> 1020.35

Sheet Cash Games
A1: Chip In
A2: Player | B2: Week 1 | C2: Week 2 | D2: Week 3 | E2: Week 4 | F2: Week 5 | G2: Week 6 | H2: Week 7 | I2: Week 8 | J2: Week 9 | K2: Week 10 | L2: Week 11 | M2: Week 12 | N2: Week 13 | O2: Week 14 | P2: Week 15 | Q2: Week 16 | R2: Week 17 | S2: Week 18 | T2: Week 19 | U2: Week 20
A3: Cody | B3: 2 | C3: 2 | D3: 2 | E3: 2 | F3: 2 | G3: 2 | H3: 2 | I3: 2 | J3: 2 | K3: 2 | L3: 2 | M3: 2 | N3: 2 | O3: 2 | P3: 2 | Q3: 2
A4: Michael | B4: 2 | C4: 2 | D4: 2 | E4: 2 | F4: 2 | G4: 2 | H4: 2 | I4: 2 | J4: 2 | K4: 2 | L4: 2 | M4: 2 | N4: 2 | O4: 2 | P4: 2 | Q4: 2
A5: Lindsay | B5: 2 | C5: 2 | D5: 2 | E5: 0 | F5: 0 | G5: 0 | H5: 0 | I5: 0 | J5: 0 | K5: 0 | L5: 2 | M5: 0 | N5: 2 | O5: 0 | P5: 0 | Q5: 2
A6: Lance | B6: 2.35 | C6: 2 | D6: 2 | E6: 2 | F6: 2 | G6: 2 | H6: 2 | I6: 2 | J6: 2 | K6: 0 | L6: 0 | M6: 0 | N6: 2 | O6: 0 | P6: 2 | Q6: 2
A7: Shea | B7: 2 | C7: 2 | D7: 2 | E7: 2 | F7: 2 | G7: 2 | H7: 2 | I7: 2 | J7: 2 | K7: 2 | L7: 2 | M7: 2 | N7: 2 | O7: 2 | P7: 2 | Q7: 2
A8: Tim | B8: 2 | C8: 2 | D8: 2 | E8: 2 | F8: 2 | G8: 2 | H8: 2 | I8: 2 | J8: 2 | K8: 2 | L8: 2 | M8: 2 | N8: 2 | O8: 0 | P8: 2 | Q8: 2
A9: Sonat | B9: 2 | C9: 2 | D9: 2 | E9: 2 | F9: 2 | G9: 2 | H9: 2 | I9: 2 | J9: 2 | K9: 2 | L9: 2 | M9: 2 | N9: 2 | O9: 2 | P9: 2 | Q9: 2
A10: Jeremy | B10: 2 | C10: 2 | D10: 2 | E10: 0 | F10: 2 | G10: 2 | H10: 2 | I10: 2 | J10: 2 | K10: 2 | L10: 2 | M10: 2 | N10: 2 | O10: 2 | P10: 2 | Q10: 2
B11: =SUM(B3:B10) -> 16.35 | C11: =SUM(C3:C10) -> 16 | D11: =SUM(D3:D10) -> 16 | E11: =SUM(E3:E10) -> 12 | F11: =SUM(F3:F10) -> 14 | G11: =SUM(G3:G10) -> 14 | H11: =SUM(H3:H10) -> 14 | I11: =SUM(I3:I10) -> 14 | ... U11: =SUM(U3:U10) -> 0
A12: Total | D12: =SUM(B11:D11) -> 48.35 | J12: =SUM(E11:J11) -> 82 | L12: =SUM(K11:L11) -> 26 | M12: =SUM(M11:M11) -> 12 | N12: =SUM(N11) -> 16 | Q12: =SUM(Q11) -> 16 | R12: =SUM(R11:U11) -> 0
A14: Player | B14: Hole In 1
A15: Cody | B15: 50
A16: Michael | B16: 50
A17: Lindsay | B17: 50
A18: Lance | B18: 50
A19: Shea | B19: 50
A20: Tim | B20: 50
A21: Sonat | B21: 50
A22: Jeremy | B22: 50
A23: Total | B23: =SUM(B15:B22) -> 400

Sheet Wk1and2 2026
A1: Paynes Valley Wk 1 | B1: 1 | C1: 2 | D1: 3 | E1: 4 | F1: 5 | G1: 6 | H1: 7 | I1: 8 | J1: 9 | K1: Total | L1: Handicap | M1: 10 | N1: 11 | O1: 12 | P1: 13 | Q1: 14 | R1: 15 | S1: 16 | T1: 17 | U1: 18 | V1: Total | W1: Handicap
A2: Par | B2: 4 | C2: 3 | D2: 4 | E2: 5 | F2: 3 | G2: 4 | H2: 4 | I2: 5 | J2: 4 | K2: =SUM(B2:J2) -> 36 | M2: 3 | N2: 4 | O2: 4 | P2: 5 | Q2: 4 | R2: 4 | S2: 3 | T2: 4 | U2: 5 | V2: =SUM(M2:U2) -> 36
A3: Player
A4: Cody | B4: 6 | C4: 4 | D4: 6 | E4: 7 | F4: 5 | G4: 6 | H4: 6 | I4: 7 | J4: 8 | K4: =SUM(B4:J4) -> 55 | M4: 3 | N4: 10 | O4: 4 | P4: 10 | Q4: 6 | R4: 6 | S4: 4 | T4: 7 | U4: 7 | V4: =SUM(M4:U4) -> 57
A5: Adjusted HC | B5: =IF(B4>B2*2,B2*2,B4) -> 6 | C5: =IF(C4>C2*2,C2*2,C4) -> 4 | D5: =IF(D4>D2*2,D2*2,D4) -> 6 | E5: =IF(E4>E2*2,E2*2,E4) -> 7 | F5: =IF(F4>F2*2,F2*2,F4) -> 5 | G5: =IF(G4>G2*2,G2*2,G4) -> 6 | H5: =IF(H4>H2*2,H2*2,H4) -> 6 | I5: =IF(I4>I2*2,I2*2,I4) -> 7 | J5: =IF(J4>J2*2,J2*2,J4) -> 8 | K5: =SUM(B5:J5) -> 55 | L5: =K5-K2 -> 19 | M5: =IF(M4>M2*2,M2*2,M4) -> 3 | N5: =IF(N4>N2*2,N2*2,N4) -> 8 | O5: =IF(O4>O2*2,O2*2,O4) -> 4 | P5: =IF(P4>P2*2,P2*2,P4) -> 10 | Q5: =IF(Q4>Q2*2,Q2*2,Q4) -> 6 | R5: =IF(R4>R2*2,R2*2,R4) -> 6 | S5: =IF(S4>S2*2,S2*2,S4) -> 4 | T5: =IF(T4>T2*2,T2*2,T4) -> 7 | U5: =IF(U4>U2*2,U2*2,U4) -> 7 | V5: =SUM(M5:U5) -> 55 | W5: =V5-V2 -> 19
A6: Michael | B6: 5 | C6: 5 | D6: 4 | E6: 6 | F6: 3 | G6: 5 | H6: 6 | I6: 5 | J6: 5 | K6: =SUM(B6:J6) -> 44 | M6: 4 | N6: 4 | O6: 4 | P6: 6 | Q6: 4 | R6: 5 | S6: 3 | T6: 5 | U6: 5 | V6: =SUM(M6:U6) -> 40
A7: Adjusted HC | B7: =IF(B6>B2*2,B2*2,B6) -> 5 | C7: =IF(C6>C2*2,C2*2,C6) -> 5 | D7: =IF(D6>D2*2,D2*2,D6) -> 4 | E7: =IF(E6>E2*2,E2*2,E6) -> 6 | F7: =IF(F6>F2*2,F2*2,F6) -> 3 | G7: =IF(G6>G2*2,G2*2,G6) -> 5 | H7: =IF(H6>H2*2,H2*2,H6) -> 6 | I7: =IF(I6>I2*2,I2*2,I6) -> 5 | J7: =IF(J6>J2*2,J2*2,J6) -> 5 | K7: =SUM(B7:J7) -> 44 | L7: =K7-K2 -> 8 | M7: =IF(M6>M2*2,M2*2,M6) -> 4 | N7: =IF(N6>N2*2,N2*2,N6) -> 4 | O7: =IF(O6>O2*2,O2*2,O6) -> 4 | P7: =IF(P6>P2*2,P2*2,P6) -> 6 | Q7: =IF(Q6>Q2*2,Q2*2,Q6) -> 4 | R7: =IF(R6>R2*2,R2*2,R6) -> 5 | S7: =IF(S6>S2*2,S2*2,S6) -> 3 | T7: =IF(T6>T2*2,T2*2,T6) -> 5 | U7: =IF(U6>U2*2,U2*2,U6) -> 5 | V7: =SUM(M7:U7) -> 40 | W7: =V7-V2 -> 4
A8: Lindsay | B8: 5 | C8: 4 | D8: 3 | E8: 6 | F8: 3 | G8: 5 | H8: 4 | I8: 5 | J8: 5 | K8: =SUM(B8:J8) -> 40 | M8: 3 | N8: 5 | O8: 3 | P8: 6 | Q8: 5 | R8: 5 | S8: 3 | T8: 5 | U8: 5 | V8: =SUM(M8:U8) -> 40
A9: Adjusted HC | B9: =IF(B8>B2*2,B2*2,B8) -> 5 | C9: =IF(C8>C2*2,C2*2,C8) -> 4 | D9: =IF(D8>D2*2,D2*2,D8) -> 3 | E9: =IF(E8>E2*2,E2*2,E8) -> 6 | F9: =IF(F8>F2*2,F2*2,F8) -> 3 | G9: =IF(G8>G2*2,G2*2,G8) -> 5 | H9: =IF(H8>H2*2,H2*2,H8) -> 4 | I9: =IF(I8>I2*2,I2*2,I8) -> 5 | J9: =IF(J8>J2*2,J2*2,J8) -> 5 | K9: =SUM(B9:J9) -> 40 | L9: =K9-K2 -> 4 | M9: =IF(M8>M2*2,M2*2,M8) -> 3 | N9: =IF(N8>N2*2,N2*2,N8) -> 5 | O9: =IF(O8>O2*2,O2*2,O8) -> 3 | P9: =IF(P8>P2*2,P2*2,P8) -> 6 | Q9: =IF(Q8>Q2*2,Q2*2,Q8) -> 5 | R9: =IF(R8>R2*2,R2*2,R8) -> 5 | S9: =IF(S8>S2*2,S2*2,S8) -> 3 | T9: =IF(T8>T2*2,T2*2,T8) -> 5 | U9: =IF(U8>U2*2,U2*2,U8) -> 5 | V9: =SUM(M9:U9) -> 40 | W9: =V9-V2 -> 4
A10: Lance | B10: 6 | C10: 4 | D10: 4 | E10: 7 | F10: 4 | G10: 6 | H10: 8 | I10: 6 | J10: 5 | K10: =SUM(B10:J10) -> 50 | M10: 5 | N10: 5 | O10: 4 | P10: 6 | Q10: 5 | R10: 6 | S10: 4 | T10: 7 | U10: 6 | V10: =SUM(M10:U10) -> 48
A11: Adjusted HC | B11: =IF(B10>B2*2,B2*2,B10) -> 6 | C11: =IF(C10>C2*2,C2*2,C10) -> 4 | D11: =IF(D10>D2*2,D2*2,D10) -> 4 | E11: =IF(E10>E2*2,E2*2,E10) -> 7 | F11: =IF(F10>F2*2,F2*2,F10) -> 4 | G11: =IF(G10>G2*2,G2*2,G10) -> 6 | H11: =IF(H10>H2*2,H2*2,H10) -> 8 | I11: =IF(I10>I2*2,I2*2,I10) -> 6 | J11: =IF(J10>J2*2,J2*2,J10) -> 5 | K11: =SUM(B11:J11) -> 50 | L11: =K11-K2 -> 14 | M11: =IF(M10>M2*2,M2*2,M10) -> 5 | N11: =IF(N10>N2*2,N2*2,N10) -> 5 | O11: =IF(O10>O2*2,O2*2,O10) -> 4 | P11: =IF(P10>P2*2,P2*2,P10) -> 6 | Q11: =IF(Q10>Q2*2,Q2*2,Q10) -> 5 | R11: =IF(R10>R2*2,R2*2,R10) -> 6 | S11: =IF(S10>S2*2,S2*2,S10) -> 4 | T11: =IF(T10>T2*2,T2*2,T10) -> 7 | U11: =IF(U10>U2*2,U2*2,U10) -> 6 | V11: =SUM(M11:U11) -> 48 | W11: =V11-V2 -> 12
A12: Shea | B12: 5 | C12: 4 | D12: 6 | E12: 5 | F12: 6 | G12: 4 | H12: 5 | I12: 4 | J12: 4 | K12: =SUM(B12:J12) -> 43 | M12: 3 | N12: 4 | O12: 5 | P12: 7 | Q12: 4 | R12: 5 | S12: 4 | T12: 5 | U12: 5 | V12: =SUM(M12:U12) -> 42
A13: Adjusted HC | B13: =IF(B12>B2*2,B2*2,B12) -> 5 | C13: =IF(C12>C2*2,C2*2,C12) -> 4 | D13: =IF(D12>D2*2,D2*2,D12) -> 6 | E13: =IF(E12>E2*2,E2*2,E12) -> 5 | F13: =IF(F12>F2*2,F2*2,F12) -> 6 | G13: =IF(G12>G2*2,G2*2,G12) -> 4 | H13: =IF(H12>H2*2,H2*2,H12) -> 5 | I13: =IF(I12>I2*2,I2*2,I12) -> 4 | J13: =IF(J12>J2*2,J2*2,J12) -> 4 | K13: =SUM(B13:J13) -> 43 | L13: =K13-K2 -> 7 | M13: =IF(M12>M2*2,M2*2,M12) -> 3 | N13: =IF(N12>N2*2,N2*2,N12) -> 4 | O13: =IF(O12>O2*2,O2*2,O12) -> 5 | P13: =IF(P12>P2*2,P2*2,P12) -> 7 | Q13: =IF(Q12>Q2*2,Q2*2,Q12) -> 4 | R13: =IF(R12>R2*2,R2*2,R12) -> 5 | S13: =IF(S12>S2*2,S2*2,S12) -> 4 | T13: =IF(T12>T2*2,T2*2,T12) -> 5 | U13: =IF(U12>U2*2,U2*2,U12) -> 5 | V13: =SUM(M13:U13) -> 42 | W13: =V13-V2 -> 6
A14: Tim | B14: 5 | C14: 4 | D14: 5 | E14: 5 | F14: 3 | G14: 5 | H14: 4 | I14: 5 | J14: 5 | K14: =SUM(B14:J14) -> 41 | M14: 3 | N14: 4 | O14: 5 | P14: 6 | Q14: 4 | R14: 5 | S14: 4 | T14: 6 | U14: 5 | V14: =SUM(M14:U14) -> 42
A15: Adjusted HC | B15: =IF(B14>B2*2,B2*2,B14) -> 5 | C15: =IF(C14>C2*2,C2*2,C14) -> 4 | D15: =IF(D14>D2*2,D2*2,D14) -> 5 | E15: =IF(E14>E2*2,E2*2,E14) -> 5 | F15: =IF(F14>F2*2,F2*2,F14) -> 3 | G15: =IF(G14>G2*2,G2*2,G14) -> 5 | H15: =IF(H14>H2*2,H2*2,H14) -> 4 | I15: =IF(I14>I2*2,I2*2,I14) -> 5 | J15: =IF(J14>J2*2,J2*2,J14) -> 5 | K15: =SUM(B15:J15) -> 41 | L15: =K15-K2 -> 5 | M15: =IF(M14>M2*2,M2*2,M14) -> 3 | N15: =IF(N14>N2*2,N2*2,N14) -> 4 | O15: =IF(O14>O2*2,O2*2,O14) -> 5 | P15: =IF(P14>P2*2,P2*2,P14) -> 6 | Q15: =IF(Q14>Q2*2,Q2*2,Q14) -> 4 | R15: =IF(R14>R2*2,R2*2,R14) -> 5 | S15: =IF(S14>S2*2,S2*2,S14) -> 4 | T15: =IF(T14>T2*2,T2*2,T14) -> 6 | U15: =IF(U14>U2*2,U2*2,U14) -> 5 | V15: =SUM(M15:U15) -> 42 | W15: =V15-V2 -> 6
A16: Sonat | B16: 5 | C16: 3 | D16: 5 | E16: 5 | F16: 3 | G16: 6 | H16: 6 | I16: 6 | J16: 4 | K16: =SUM(B16:J16) -> 43 | M16: 3 | N16: 4 | O16: 3 | P16: 4 | Q16: 6 | R16: 5 | S16: 3 | T16: 5 | U16: 6 | V16: =SUM(M16:U16) -> 39
A17: Adjusted HC | B17: =IF(B16>B2*2,B2*2,B16) -> 5 | C17: =IF(C16>C2*2,C2*2,C16) -> 3 | D17: =IF(D16>D2*2,D2*2,D16) -> 5 | E17: =IF(E16>E2*2,E2*2,E16) -> 5 | F17: =IF(F16>F2*2,F2*2,F16) -> 3 | G17: =IF(G16>G2*2,G2*2,G16) -> 6 | H17: =IF(H16>H2*2,H2*2,H16) -> 6 | I17: =IF(I16>I2*2,I2*2,I16) -> 6 | J17: =IF(J16>J2*2,J2*2,J16) -> 4 | K17: =SUM(B17:J17) -> 43 | L17: =K17-K2 -> 7 | M17: =IF(M16>M2*2,M2*2,M16) -> 3 | N17: =IF(N16>N2*2,N2*2,N16) -> 4 | O17: =IF(O16>O2*2,O2*2,O16) -> 3 | P17: =IF(P16>P2*2,P2*2,P16) -> 4 | Q17: =IF(Q16>Q2*2,Q2*2,Q16) -> 6 | R17: =IF(R16>R2*2,R2*2,R16) -> 5 | S17: =IF(S16>S2*2,S2*2,S16) -> 3 | T17: =IF(T16>T2*2,T2*2,T16) -> 5 | U17: =IF(U16>U2*2,U2*2,U16) -> 6 | V17: =SUM(M17:U17) -> 39 | W17: =V17-V2 -> 3
A18: Jeremy | B18: 6 | C18: 5 | D18: 5 | E18: 8 | F18: 4 | G18: 5 | H18: 5 | I18: 6 | J18: 6 | K18: =SUM(B18:J18) -> 50 | M18: 5 | N18: 4 | O18: 5 | P18: 7 | Q18: 5 | R18: 6 | S18: 4 | T18: 7 | U18: 6 | V18: =SUM(M18:U18) -> 49
A19: Adjusted HC | B19: =IF(B18>B2*2,B2*2,B18) -> 6 | C19: =IF(C18>C2*2,C2*2,C18) -> 5 | D19: =IF(D18>D2*2,D2*2,D18) -> 5 | E19: =IF(E18>E2*2,E2*2,E18) -> 8 | F19: =IF(F18>F2*2,F2*2,F18) -> 4 | G19: =IF(G18>G2*2,G2*2,G18) -> 5 | H19: =IF(H18>H2*2,H2*2,H18) -> 5 | I19: =IF(I18>I2*2,I2*2,I18) -> 6 | J19: =IF(J18>J2*2,J2*2,J18) -> 6 | K19: =SUM(B19:J19) -> 50 | L19: =K19-K2 -> 14 | M19: =IF(M18>M2*2,M2*2,M18) -> 5 | N19: =IF(N18>N2*2,N2*2,N18) -> 4 | O19: =IF(O18>O2*2,O2*2,O18) -> 5 | P19: =IF(P18>P2*2,P2*2,P18) -> 7 | Q19: =IF(Q18>Q2*2,Q2*2,Q18) -> 5 | R19: =IF(R18>R2*2,R2*2,R18) -> 6 | S19: =IF(S18>S2*2,S2*2,S18) -> 4 | T19: =IF(T18>T2*2,T2*2,T18) -> 7 | U19: =IF(U18>U2*2,U2*2,U18) -> 6 | V19: =SUM(M19:U19) -> 49 | W19: =V19-V2 -> 13
C20: 196 yrd | F20: 120 yrd | M20: 139 yrd | S20: 172 yrd
A22: Closest Too
A23: Player | B23: Week 1 | C23: Week 2
A24: Cody | B24: - | C24: -
A25: Michael | B25: - | C25: 15.1
A26: Lindsay | B26: - | C26: -
A27: Lance | B27: - | C27: -
A28: Shea | B28: - | C28: -
A29: Tim | B29: 11.8 | C29: 14.5
A30: Sonat | B30: 18.8 | C30: -
A31: Jeremy | B31: - | C31: -

Sheet New Adj Cap 2026
A1: Player | B1: Week 1 | C1: Week 2 | D1: Week 3 | E1: Week 4 | F1: Week 5 | G1: Week 6 | H1: Week 7 | I1: Week 8 | J1: total | K1: rounds | L1: Ave 9 score | M1: new cap | N1: old
A2: Cody | B2: ='Wk1and2 2026'!K4 -> 55 | C2: ='Wk1and2 2026'!V4 -> 57 | D2: 56 | E2: 58 | F2: 59 | G2: 64 | H2: 54 | I2: 57 | J2: =SUM(B2:I2) -> 460 | K2: 8 | L2: =J2/K2 -> 57.5 | M2: =L2-E12 -> 21.5 | N2: 19
A3: Jeremy | B3: ='Wk1and2 2026'!K18 -> 50 | C3: ='Wk1and2 2026'!V18 -> 49 | D3: 63 | E3: 54 | F3: 61 | G3: 56 | H3: 54 | I3: 61 | J3: =SUM(B3:I3) -> 448 | K3: 8 | L3: =J3/K3 -> 56 | M3: =L3-E12 -> 20 | N3: 13.5
A4: Lance | B4: ='Wk1and2 2026'!K10 -> 50 | C4: ='Wk1and2 2026'!V10 -> 48 | D4: 45 | E4: 63 | F4: 57 | G4: 62 | H4: 51 | I4: 55 | J4: =SUM(B4:I4) -> 431 | K4: 8 | L4: =J4/K4 -> 53.875 | M4: =L4-E12 -> 17.875 | N4: 13
A5: Shea | B5: ='Wk1and2 2026'!K12 -> 43 | C5: ='Wk1and2 2026'!V12 -> 42 | D5: 43 | E5: 41 | F5: 38 | G5: 42 | H5: 41 | I5: 43 | J5: =SUM(B5:I5) -> 333 | K5: 8 | L5: =J5/K5 -> 41.625 | M5: =L5-E12 -> 5.625 | N5: 6.5
A6: Michael | B6: ='Wk1and2 2026'!K6 -> 44 | C6: ='Wk1and2 2026'!V6 -> 40 | D6: 44 | E6: 43 | F6: 44 | G6: 45 | H6: 47 | I6: 48 | J6: =SUM(B6:I6) -> 355 | K6: 8 | L6: =J6/K6 -> 44.375 | M6: =L6-E12 -> 8.375 | N6: 6
A7: Tim | B7: ='Wk1and2 2026'!K14 -> 41 | C7: ='Wk1and2 2026'!V14 -> 42 | D7: 45 | E7: 41 | F7: 45 | G7: 43 | H7: 44 | I7: 41 | J7: =SUM(B7:I7) -> 342 | K7: 8 | L7: =J7/K7 -> 42.75 | M7: =L7-E12 -> 6.75 | N7: 5.5
A8: Sonat | B8: ='Wk1and2 2026'!K16 -> 43 | C8: ='Wk1and2 2026'!V16 -> 39 | D8: 43 | E8: 45 | F8: 51 | G8: 48 | H8: 39 | I8: 39 | J8: =SUM(B8:I8) -> 347 | K8: 8 | L8: =J8/K8 -> 43.375 | M8: =L8-E12 -> 7.375 | N8: 5
A9: Lindsay | B9: ='Wk1and2 2026'!K8 -> 40 | C9: ='Wk1and2 2026'!V8 -> 40 | D9: 40 | E9: 40 | F9: 0 | G9: 0 | H9: 0 | I9: 0 | J9: =SUM(B9:I9) -> 160 | K9: 4 | L9: =J9/K9 -> 40 | M9: =L9-E12 -> 4 | N9: 4
D12: Ave 9 hole | E12: 36
A14: Player | B14: Week 1 | C14: Week 2 | D14: Week 3 | E14: Week 4 | F14: Week 5 | G14: Week 6 | H14: Week 7 | I14: Week 8 | J14: Week 9 | K14: Week 10 | L14: Week 11 | M14: Week 12 | N14: Week 13 | O14: Week 14 | P14: total | Q14: rounds | R14: ave 9 score | S14: new cap | T14: old
A15: Cody | B15: 55 | C15: 57 | D15: 56 | E15: 58 | F15: 59 | G15: 64 | H15: 54 | I15: 57 | J15: 60 | K15: 57 | L15: 56 | M15: 54 | N15: 58 | O15: 41 | P15: =SUM(B15:O15) -> 786 | Q15: 14 | R15: =P15/Q15 -> 56.142857 | S15: 21 | T15: 22
A16: Jeremy | B16: 50 | C16: 49 | D16: 63 | E16: 54 | F16: 61 | G16: 56 | H16: 54 | I16: 61 | J16: 55 | K16: 57 | L16: 55 | M16: 56 | N16: 51 | O16: 49 | P16: =SUM(B16:O16) -> 771 | Q16: 14 | R16: =P16/Q16 -> 55.071429 | S16: 20 | T16: 20
A17: Lance | B17: 50 | C17: 48 | D17: 45 | E17: 63 | F17: 57 | G17: 62 | H17: 51 | I17: 55 | J17: 50 | K17: 58 | L17: 57 | M17: 59 | N17: 55 | O17: 44 | P17: =SUM(B17:O17) -> 754 | Q17: 14 | R17: =P17/Q17 -> 53.857143 | S17: 18 | T17: 18
A18: Shea | B18: 43 | C18: 42 | D18: 43 | E18: 41 | F18: 38 | G18: 42 | H18: 41 | I18: 43 | J18: 42 | K18: 39 | L18: 43 | M18: 36 | N18: 40 | O18: 39 | P18: =SUM(B18:O18) -> 572 | Q18: 14 | R18: =P18/Q18 -> 40.857143 | S18: 5 | T18: 6
A19: Michael | B19: 44 | C19: 40 | D19: 44 | E19: 43 | F19: 44 | G19: 45 | H19: 47 | I19: 48 | J19: 43 | K19: 48 | L19: 38 | M19: 41 | N19: 40 | O19: 37 | P19: =SUM(B19:O19) -> 602 | Q19: 14 | R19: =P19/Q19 -> 43 | S19: 7 | T19: 8
A20: Tim | B20: 41 | C20: 42 | D20: 45 | E20: 41 | F20: 45 | G20: 43 | H20: 44 | I20: 41 | J20: 46 | K20: 41 | L20: 39 | M20: 44 | N20: 41 | O20: 43 | P20: =SUM(B20:O20) -> 596 | Q20: 14 | R20: =P20/Q20 -> 42.571429 | S20: 7 | T20: 7
A21: Sonat | B21: 43 | C21: 39 | D21: 43 | E21: 45 | F21: 51 | G21: 48 | H21: 39 | I21: 39 | J21: 43 | K21: 46 | L21: 44 | M21: 38 | N21: 44 | O21: 37 | P21: =SUM(B21:O21) -> 599 | Q21: 14 | R21: =P21/Q21 -> 42.785714 | S21: 7 | T21: 7
A22: Lindsay | B22: 40 | C22: 40 | D22: 40 | E22: 40 | F22: 0 | G22: 0 | H22: 0 | I22: 0 | J22: 0 | K22: 0 | L22: 0 | M22: 0 | N22: 42 | O22: 0 | P22: =SUM(B22:O22) -> 202 | Q22: 5 | R22: =P22/Q22 -> 40.4 | S22: 5 | T22: 4
D24: Ave 9 hole | E24: 35.6

Sheet Total Prize Money 2025
A2: Player | B2: Tourney $ | C2: Closest Too | D2: Total
A3: Cody | D3: =SUM(B3:C3) -> 0
A4: Lindsay | C4: 80 | D4: =SUM(B4:C4) -> 80
A5: Lance | D5: =SUM(B5:C5) -> 0
A6: Shea | B6: 400 | C6: 160 | D6: =SUM(B6:C6) -> 560
A7: Tim | B7: 100 | C7: 40 | D7: =SUM(B7:C7) -> 140
A8: Sonat | B8: 50 | C8: 60 | D8: =SUM(B8:C8) -> 110
A9: Jeremy | B9: 200 | D9: =SUM(B9:C9) -> 200
A10: Jordan | C10: 20 | D10: =SUM(B10:C10) -> 20
D11: =SUM(D3:D10) -> 1110

Sheet Leaderboard 2025
A1: Player | B1: Sum of Total
A2: Tim | B2: 96
A3: Jeremy | B3: 94.5
A4: Sonat | B4: 94
A5: Shea | B5: 90.5
A6: Cody | B6: 76
A7: Lance | B7: 70
A8: Jordan | B8: 62
A9: Lindsay | B9: 59
A10: Grand Total | B10: 642
A12: Tournament 1 | P12: Closest Too
A13: Player | B13: Week 1 | C13: Points | D13: Week 2 | E13: Points | F13: Week 3 | G13: Points | H13: Week 4 | I13: Points | J13: Week 5 | K13: Points | L13: Week 6 | M13: Points | N13: Total | P13: Player | Q13: Total | R13: Week 1 | S13: Week 2 | T13: Week 3 | U13: Week 4 | V13: Week 5 | W13: Week 6 | X13: Week 7 | Y13: Week 8 | Z13: Week 9 | AA13: Week 10 | AB13: Week 11 | AC13: Week 12 | AD13: Week 13 | AE13: Week 14 | AF13: Week 15 | AG13: Week 16 | AH13: Week 17 | AI13: Week 18
A14: Cody | B14: 38.5 | C14: 3 | D14: -25.5 | E14: 1 | F14: -25.5 | G14: 1 | H14: 34.5 | I14: 6 | J14: 27.5 | K14: 8 | L14: 30.5 | M14: 7 | N14: 26 | P14: Cody | Q14: 0 | R14: - | S14: - | T14: - | U14: - | V14: - | W14: - | X14: - | Y14: - | Z14: - | AA14: - | AB14: - | AC14: - | AF14: - | AH14: - | AI14: -
A15: Jordan | B15: 32.5 | C15: 6 | D15: 41.5 | E15: 2 | F15: 38.5 | G15: 2 | H15: -10.5 | I15: 1 | J15: 47.5 | K15: 3 | L15: -10.5 | M15: 1 | N15: 15 | P15: Jordan | Q15: 1 | R15: 6.5 | S15: - | T15: - | U15: - | V15: - | W15: - | X15: - | Y15: - | Z15: - | AA15: - | AB15: - | AC15: - | AF15: - | AH15: 11.5 | AI15: 15.6
A16: Lindsay | B16: 36 | C16: 5 | D16: 37 | E16: 5 | F16: 32 | G16: 4 | H16: 35 | I16: 5 | J16: 34 | K16: 5.5 | L16: 34 | M16: 2.5 | N16: 27 | P16: Lindsay | Q16: 4 | R16: - | S16: - | T16: 10.7 | U16: - | V16: - | W16: 9.5 | X16: 9.9 | Y16: - | Z16: - | AA16: 20 | AB16: 8.2 | AC16: - | AF16: - | AI16: -
A17: Lance | B17: 40 | C17: 2 | D17: 39 | E17: 4 | F17: 38 | G17: 3 | H17: 38 | I17: 2 | J17: 34 | K17: 5.5 | L17: 34 | M17: 2.5 | N17: 19 | P17: Lance | Q17: 0 | R17: - | S17: - | T17: - | U17: - | V17: - | W17: - | X17: - | Y17: - | Z17: - | AA17: - | AB17: - | AC17: - | AF17: - | AH17: 17.7 | AI17: -
A18: Shea | B18: 31.5 | C18: 7 | D18: 29.5 | E18: 8 | F18: 25.5 | G18: 8 | H18: 28.5 | I18: 8 | J18: -12.5 | K18: 1 | L18: 28.5 | M18: 8 | N18: 40 | P18: Shea | Q18: 8 | R18: - | S18: - | T18: 7.8 | U18: 20.6 | V18: - | W18: - | X18: - | Y18: 6.3 | Z18: 8 | AA18: 4.2 | AB18: - | AC18: - | AF18: 11.9 | AH18: 6.1 | AI18: 12.9
A19: Tim | B19: 30 | C19: 8 | D19: 33 | E19: 7 | F19: 30 | G19: 5 | H19: 34 | I19: 7 | J19: -12 | K19: 1 | L19: 32 | M19: 5 | N19: 33 | P19: Tim | Q19: 2 | R19: 17.9 | S19: - | T19: 11.7 | U19: - | V19: - | W19: - | X19: - | Y19: 8.3 | Z19: 12 | AA19: - | AB19: 8.8 | AC19: 10.9 | AF19: - | AH19: - | AI19: -
A20: Sonat | B20: 36.5 | C20: 4 | D20: 33.5 | E20: 6 | F20: 26.5 | G20: 7 | H20: 37.5 | I20: 4 | J20: 30.5 | K20: 7 | L20: 32.5 | M20: 4 | N20: 32 | P20: Sonat | Q20: 3 | R20: - | S20: - | T20: - | U20: - | V20: winner | W20: - | X20: 21.3 | Y20: 8.7 | Z20: - | AA20: - | AB20: 4.6 | AC20: - | AF20: 13.2 | AH20: 0,9 | AI20: -
A21: Jeremy | B21: -23 | C21: 1 | D21: 39 | E21: 3 | F21: 29 | G21: 6 | H21: 38 | I21: 3 | J21: 46 | K21: 4 | L21: 31 | M21: 6 | N21: 23 | P21: Jeremy | Q21: 0 | R21: - | S21: - | T21: - | U21: - | V21: - | W21: - | X21: - | Y21: - | Z21: - | AA21: - | AB21: - | AC21: - | AF21: - | AH21: - | AI21: -
A23: Tournament 2
A24: Player | B24: Week 1 | C24: Points | D24: Week 2 | E24: Points | F24: Week 3 | G24: Points | H24: Week 4 | I24: Points | J24: Week 5 | K24: Points | L24: Week 6 | M24: Points | N24: Total
A25: Cody | B25: 40 | C25: 2.5 | D25: 39 | E25: 3 | F25: 31 | G25: 5.5 | H25: 36 | I25: 3.5 | J25: 34 | K25: 5 | L25: 37 | M25: 6 | N25: =C25+E25+G25+I25+K25+M25 -> 25.5
A26: Jordan | B26: 35 | C26: 6 | D26: 27 | E26: 8 | F26: 37 | G26: 3 | H26: 33 | I26: 6.5 | J26: -14 | K26: 1 | L26: -14 | M26: 1 | N26: =C26+E26+G26+I26+K26+M26 -> 25.5
A27: Lindsay | B27: 40 | C27: 2.5 | D27: -6 | E27: 1 | F27: -6 | G27: 1 | H27: 41 | I27: 1 | J27: 39 | K27: 3 | L27: -6 | M27: 1 | N27: =C27+E27+G27+I27+K27+M27 -> 9.5
A28: Lance | B28: 27 | C28: 8 | D28: 29 | E28: 7 | F28: -24 | G28: 1 | H28: 26 | I28: 8 | J28: -24 | K28: 1 | L28: -24 | M28: 1 | N28: =C28+E28+G28+I28+K28+M28 -> 26
A29: Shea | B29: 37 | C29: 4 | D29: 32 | E29: 6 | F29: 30 | G29: 7 | H29: 33 | I29: 6.5 | J29: 37 | K29: 4 | L29: 39 | M29: 5 | N29: =C29+E29+G29+I29+K29+M29 -> 32.5
A30: Tim | B30: 29 | C30: 7 | D30: 33 | E30: 4.5 | F30: 32 | G30: 4 | H30: 37 | I30: 2 | J30: 31 | K30: 6 | L30: 33 | M30: 8 | N30: =C30+E30+G30+I30+K30+M30 -> 31.5
A31: Sonat | B31: 36 | C31: 5 | D31: 33 | E31: 4.5 | F31: 31 | G31: 5.5 | H31: 36 | I31: 3.5 | J31: 29 | K31: 8 | L31: 42 | M31: 4 | N31: =C31+E31+G31+I31+K31+M31 -> 30.5
A32: Jeremy | B32: -25 | C32: 1 | D32: 48 | E32: 2 | F32: 29 | G32: 8 | H32: 35 | I32: 5 | J32: 30 | K32: 7 | L32: 34 | M32: 7 | N32: =C32+E32+G32+I32+K32+M32 -> 30
A34: Tournament 3
A35: Player | B35: Week 1 | C35: Points | D35: Week 2 | E35: Points | F35: Week 3 | G35: Points | H35: Week 4 | I35: Points | J35: Week 5 | K35: Points | L35: Week 6 | M35: Points | N35: Total
A36: Cody | B36: 49.708333 | C36: 2 | D36: 38.708333 | E36: 3 | F36: 34.708333 | G36: 6 | H36: 47.708333 | I36: 3 | J36: 29.708333 | K36: 6 | L36: 34.708333 | M36: 4.5 | N36: =C36+E36+G36+I36+K36+M36 -> 24.5
A37: Jordan | B37: 43.325 | C37: 4 | D37: 31.325 | E37: 7 | F37: 46.325 | G37: 1 | H37: 50.325 | I37: 1.5 | J37: 31.325 | K37: 5 | L37: 36.325 | M37: 3 | N37: =C37+E37+G37+I37+K37+M37 -> 21.5
A38: Lindsay | B38: 36.534091 | C38: 6 | D38: 35.534091 | E38: 4.5 | F38: 35.534091 | G38: 5 | H38: 40.534091 | I38: 5 | J38: -7.4659091 | K38: 1 | L38: -7.4659091 | M38: 1 | N38: =C38+E38+G38+I38+K38+M38 -> 22.5
A39: Lance | B39: 36.443182 | C39: 7 | D39: 53.443182 | E39: 2 | F39: 31.443182 | G39: 7 | H39: 50.443182 | I39: 1.5 | J39: 34.443182 | K39: 3 | L39: 35.443182 | M39: 4.5 | N39: =C39+E39+G39+I39+K39+M39 -> 25
A40: Shea | B40: -7.375 | C40: 1 | D40: -7.375 | E40: 1 | F40: 36.625 | G40: 4 | H40: 38.625 | I40: 6 | J40: 31.625 | K40: 4 | L40: 37.625 | M40: 2 | N40: =C40+E40+G40+I40+K40+M40 -> 18
A41: Tim | B41: 35.240385 | C41: 8 | D41: 36.240385 | E41: 4.5 | F41: 40.240385 | G41: 2 | H41: 37.240385 | I41: 8 | J41: 36.240385 | K41: 2 | L41: 31.240385 | M41: 7 | N41: =C41+E41+G41+I41+K41+M41 -> 31.5
A42: Sonat | B42: 38.767857 | C42: 5 | D42: 34.767857 | E42: 6 | F42: 38.767857 | G42: 3 | H42: 41.767857 | I42: 4 | J42: 26.767857 | K42: 7.5 | L42: 31.767857 | M42: 6 | N42: =C42+E42+G42+I42+K42+M42 -> 31.5
A43: Jeremy | B43: 47.041667 | C43: 3 | D43: 27.041667 | E43: 8 | F43: 30.041667 | G43: 8 | H43: 38.041667 | I43: 7 | J43: 27.041667 | K43: 7.5 | L43: 28.041667 | M43: 8 | N43: =C43+E43+G43+I43+K43+M43 -> 41.5

Sheet Tournament 1
A1: Player | B1: Sum of Total
A2: Shea | B2: 40
A3: Tim | B3: 33
A4: Sonat | B4: 32
A5: Lindsay | B5: 27
A6: Cody | B6: 26
A7: Jeremy | B7: 23
A8: Lance | B8: 19
A9: Jordan | B9: 15
A10: Grand Total | B10: 215
A12: Tournament 1 | P12: Points | R12: *split points if tied* | T12: Closest Too
A13: Player | B13: Week 1 | C13: Points | D13: Week 2 | E13: Points | F13: Week 3 | G13: Points | H13: Week 4 | I13: Points | J13: Week 5 | K13: Points | L13: Week 6 | M13: Points | N13: Total | P13: 1st | Q13: 8 | T13: Player | U13: Week 1 | V13: Week 2 | W13: Week 3 | X13: Week 4 | Y13: Week 5 | Z13: Week 6
A14: Cody | B14: =M26 -> 38.5 | C14: 3 | D14: =Y26 -> -25.5 | E14: 1 | F14: =M39 -> -25.5 | G14: 1 | H14: =Y39 -> 34.5 | I14: 6 | J14: =M52 -> 27.5 | K14: 8 | L14: =Y52 -> 30.5 | M14: 7 | N14: =C14+E14+G14+I14+K14+M14 -> 26 | P14: 2nd | Q14: 7 | T14: Cody | U14: - | V14: - | W14: - | X14: - | Y14: - | Z14: -
A15: Jordan | B15: =M27 -> 32.5 | C15: 6 | D15: =Y27 -> 41.5 | E15: 2 | F15: =M40 -> 38.5 | G15: 2 | H15: =Y40 -> -10.5 | I15: 1 | J15: =M53 -> 47.5 | K15: 3 | L15: =Y53 -> -10.5 | M15: 1 | N15: =C15+E15+G15+I15+K15+M15 -> 15 | P15: 3rd | Q15: 6 | T15: Jordan | U15: 6.5 | V15: - | W15: - | X15: - | Y15: - | Z15: -
A16: Lindsay | B16: =M28 -> 36 | C16: 5 | D16: =Y28 -> 37 | E16: 5 | F16: =M41 -> 32 | G16: 4 | H16: =Y41 -> 35 | I16: 5 | J16: =M54 -> 34 | K16: 5.5 | L16: =Y54 -> 34 | M16: 2.5 | N16: =C16+E16+G16+I16+K16+M16 -> 27 | P16: 4th | Q16: 5 | T16: Lindsay | U16: - | V16: - | W16: 10.7 | X16: - | Y16: - | Z16: 9.5
A17: Lance | B17: =M29 -> 40 | C17: 2 | D17: =Y29 -> 39 | E17: 4 | F17: =M42 -> 38 | G17: 3 | H17: =Y42 -> 38 | I17: 2 | J17: =M55 -> 34 | K17: 5.5 | L17: =Y55 -> 34 | M17: 2.5 | N17: =C17+E17+G17+I17+K17+M17 -> 19 | P17: 5th | Q17: 4 | T17: Lance | U17: - | V17: - | W17: - | X17: - | Y17: - | Z17: -
A18: Shea | B18: =M30 -> 31.5 | C18: 7 | D18: =Y30 -> 29.5 | E18: 8 | F18: =M43 -> 25.5 | G18: 8 | H18: =Y43 -> 28.5 | I18: 8 | J18: =M56 -> -12.5 | K18: 1 | L18: =Y56 -> 28.5 | M18: 8 | N18: =C18+E18+G18+I18+K18+M18 -> 40 | P18: 6th | Q18: 3 | T18: Shea | U18: - | V18: - | W18: 7.8 | X18: 20.6 | Y18: - | Z18: -
A19: Tim | B19: =M31 -> 30 | C19: 8 | D19: =Y31 -> 33 | E19: 7 | F19: =M44 -> 30 | G19: 5 | H19: =Y44 -> 34 | I19: 7 | J19: =M57 -> -12 | K19: 1 | L19: =Y57 -> 32 | M19: 5 | N19: =C19+E19+G19+I19+K19+M19 -> 33 | P19: 7th | Q19: 2 | T19: Tim | U19: 17.9 | V19: - | W19: 11.7 | X19: - | Y19: - | Z19: -
A20: Sonat | B20: =M32 -> 36.5 | C20: 4 | D20: =Y32 -> 33.5 | E20: 6 | F20: =M45 -> 26.5 | G20: 7 | H20: =Y45 -> 37.5 | I20: 4 | J20: =M58 -> 30.5 | K20: 7 | L20: =Y58 -> 32.5 | M20: 4 | N20: =C20+E20+G20+I20+K20+M20 -> 32 | P20: 8th | Q20: 1 | T20: Sonat | U20: - | V20: - | W20: - | X20: - | Y20: winner | Z20: -
A21: Jeremy | B21: =M33 -> -23 | C21: 1 | D21: =Y33 -> 39 | E21: 3 | F21: =M46 -> 29 | G21: 6 | H21: =Y46 -> 38 | I21: 3 | J21: =M59 -> 46 | K21: 4 | L21: =Y59 -> 31 | M21: 6 | N21: =C21+E21+G21+I21+K21+M21 -> 23 | T21: Jeremy | U21: - | V21: - | W21: - | X21: - | Y21: - | Z21: -
A23: Grove XXIII | B23: 1 | C23: 2 | D23: 3 | E23: 4 | F23: 5 | G23: 6 | H23: 7 | I23: 8 | J23: 9 | K23: Total | L23: Handicap | M23: Score | N23: 10 | O23: 11 | P23: 12 | Q23: 13 | R23: 14 | S23: 15 | T23: 16 | U23: 17 | V23: 18 | W23: Total | X23: Handicap | Y23: Score
A24: Par | B24: 4 | C24: 4 | D24: 3 | E24: 5 | F24: 4 | G24: 4 | H24: 3 | I24: 5 | J24: 4 | K24: =SUM(B24:J24) -> 36 | N24: 4 | O24: 5 | P24: 4 | Q24: 3 | R24: 4 | S24: 3 | T24: 4 | U24: 5 | V24: 4 | W24: =SUM(N24:V24) -> 36
A25: Player
A26: Cody | B26: 5 | C26: 7 | D26: 4 | E26: 8 | F26: 6 | G26: 7 | H26: 4 | I26: 12 | J26: 11 | K26: =SUM(B26:J26) -> 64 | L26: 25.5 | M26: =K26-L26 -> 38.5 | W26: =SUM(N26:V26) -> 0 | X26: 25.5 | Y26: =W26-X26 -> -25.5
A27: Jordan | B27: 4 | C27: 4 | D27: 6 | E27: 6 | F27: 5 | G27: 5 | H27: 3 | I27: 6 | J27: 4 | K27: =SUM(B27:J27) -> 43 | L27: 10.5 | M27: =K27-L27 -> 32.5 | N27: 6 | O27: 6 | P27: 6 | Q27: 5 | R27: 7 | S27: 5 | T27: 5 | U27: 6 | V27: 6 | W27: =SUM(N27:V27) -> 52 | X27: 10.5 | Y27: =W27-X27 -> 41.5
A28: Lindsay | B28: 5 | C28: 5 | D28: 4 | E28: 5 | F28: 4 | G28: 3 | H28: 4 | I28: 9 | J28: 4 | K28: =SUM(B28:J28) -> 43 | L28: 7 | M28: =K28-L28 -> 36 | N28: 4 | O28: 7 | P28: 5 | Q28: 3 | R28: 5 | S28: 3 | T28: 6 | U28: 7 | V28: 4 | W28: =SUM(N28:V28) -> 44 | X28: 7 | Y28: =W28-X28 -> 37
A29: Lance | B29: 7 | C29: 5 | D29: 6 | E29: 9 | F29: 6 | G29: 8 | H29: 5 | I29: 10 | J29: 6 | K29: =SUM(B29:J29) -> 62 | L29: 22 | M29: =K29-L29 -> 40 | N29: 6 | O29: 7 | P29: 6 | Q29: 5 | R29: 8 | S29: 8 | T29: 8 | U29: 7 | V29: 6 | W29: =SUM(N29:V29) -> 61 | X29: 22 | Y29: =W29-X29 -> 39
A30: Shea | B30: 5 | C30: 4 | D30: 3 | E30: 6 | F30: 3 | G30: 9 | H30: 4 | I30: 5 | J30: 5 | K30: =SUM(B30:J30) -> 44 | L30: 12.5 | M30: =K30-L30 -> 31.5 | N30: 4 | O30: 6 | P30: 5 | Q30: 4 | R30: 5 | S30: 3 | T30: 4 | U30: 6 | V30: 5 | W30: =SUM(N30:V30) -> 42 | X30: 12.5 | Y30: =W30-X30 -> 29.5
A31: Tim | B31: 6 | C31: 5 | D31: 4 | E31: 5 | F31: 4 | G31: 5 | H31: 4 | I31: 5 | J31: 4 | K31: =SUM(B31:J31) -> 42 | L31: 12 | M31: =K31-L31 -> 30 | N31: 4 | O31: 7 | P31: 5 | Q31: 3 | R31: 7 | S31: 4 | T31: 4 | U31: 6 | V31: 5 | W31: =SUM(N31:V31) -> 45 | X31: 12 | Y31: =W31-X31 -> 33
A32: Sonat | B32: 5 | C32: 5 | D32: 5 | E32: 7 | F32: 5 | G32: 5 | H32: 5 | I32: 7 | J32: 5 | K32: =SUM(B32:J32) -> 49 | L32: 12.5 | M32: =K32-L32 -> 36.5 | N32: 6 | O32: 5 | P32: 5 | Q32: 5 | R32: 6 | S32: 4 | T32: 4 | U32: 5 | V32: 6 | W32: =SUM(N32:V32) -> 46 | X32: 12.5 | Y32: =W32-X32 -> 33.5
A33: Jeremy | K33: =SUM(B33:J33) -> 0 | L33: 23 | M33: =K33-L33 -> -23 | N33: 6 | O33: 8 | P33: 7 | Q33: 6 | R33: 8 | S33: 4 | T33: 8 | U33: 7 | V33: 8 | W33: =SUM(N33:V33) -> 62 | X33: 23 | Y33: =W33-X33 -> 39
D34: 210 yrd | H34: 155 yrd | Q34: 193 yrd | S34: 126 yrd
