Workbook

Sheet Export Summary
B3: This document was exported from Numbers. Each table was converted to an Excel worksheet. All other objects on each Numbers sheet were placed on separate worksheets. Please be aware that formula calculations may differ in Excel.
B7: Numbers Sheet Name | C7: Numbers Table Name | D7: Excel Worksheet Name
B9: Total Prize Money 2025
C10: Table 1 | D10: Total Prize Money 2025
B11: Leaderboard 2025
C12: PivotTable1 | D12: Leaderboard 2025 - PivotTable1
C13: Table 1 | D13: Leaderboard 2025 - Table 1
B14: Tournament 1
C15: PivotTable3 | D15: Tournament 1 - PivotTable3
C16: Table 1 | D16: Tournament 1 - Table 1
B17: Tournament 2
C18: PivotTable4 | D18: Tournament 2 - PivotTable4
C19: Table 1 | D19: Tournament 2 - Table 1
B20: Tournament 3
C21: PivotTable4 | D21: Tournament 3 - PivotTable4
C22: Table 1 | D22: Tournament 3 - Table 1
B23: Handicap Summary
C24: Table 1 | D24: Handicap Summary
B25: Wk1and2
C26: Table 1 | D26: Wk1and2
B27: New Adj Cap
C28: Table 1 | D28: New Adj Cap

Sheet Total Prize Money 2025
A2: Player | B2: Tourney $ | C2: Closest Too | D2: Total
A3: Cody | D3: {=SUM(B3:C3)} -> 0
A4: Lindsay | C4: 80 | D4: {=SUM(B4:C4)} -> 80
A5: Lance | D5: {=SUM(B5:C5)} -> 0
A6: Shea | B6: 400 | C6: 160 | D6: {=SUM(B6:C6)} -> 560
A7: Tim | B7: 100 | C7: 40 | D7: {=SUM(B7:C7)} -> 140
A8: Sonat | B8: 50 | C8: 60 | D8: {=SUM(B8:C8)} -> 110
A9: Jeremy | B9: 200 | D9: {=SUM(B9:C9)} -> 200
A10: Jordan | C10: 20 | D10: {=SUM(B10:C10)} -> 20
D11: {=SUM(D3:D10)} -> 1110

Sheet Leaderboard 2025 - PivotTable1
A1: PivotTable1
A2: Player | B2: Total (Sum)
A3: Tim | B3: 96
A4: Jeremy | B4: 94.5
A5: Sonat | B5: 94
A6: Shea | B6: 90.5
A7: Cody | B7: 76
A8: Lance | B8: 70
A9: Jordan | B9: 62
A10: Lindsay | B10: 59
A11: Grand Total | B11: 642

Sheet Leaderboard 2025 - Table 1
A12: Tournament 1 | P12: Closest Too
A13: Player | B13: Week 1 | C13: Points | D13: Week 2 | E13: Points | F13: Week 3 | G13: Points | H13: Week 4 | I13: Points | J13: Week 5 | K13: Points | L13: Week 6 | M13: Points | N13: Total | P13: Player | Q13: Total | R13: Week 1 | S13: Week 2 | T13: Week 3 | U13: Week 4 | V13: Week 5 | W13: Week 6 | X13: Week 7 | Y13: Week 8 | Z13: Week 9 | AA13: Week 10 | AB13: Week 11 | AC13: Week 12 | AD13: Week 13 | AE13: Week 14 | AF13: Week 15 | AG13: Week 16 | AH13: Week 17 | AI13: Week 18
A14: Cody | B14: 38.5 | C14: 3 | D14: -25.5 | E14: 1 | F14: -25.5 | G14: 1 | H14: 34.5 | I14: 6 | J14: 27.5 | K14: 8 | L14: 30.5 | M14: 7 | N14: 26 | P14: Cody | Q14: 0 | R14: - | S14: - | T14: - | U14: - | V14: - | W14: - | X14: - | Y14: - | Z14: - | AA14: - | AB14: - | AC14: - | AF14: - | AH14: - | AI14: -
A15: Jordan | B15: 32.5 | C15: 6 | D15: 41.5 | E15: 2 | F15: 38.5 | G15: 2 | H15: -10.5 | I15: 1 | J15: 47.5 | K15: 3 | L15: -10.5 | M15: 1 | N15: 15 | P15: Jordan | Q15: 1 | R15: 6.5 | S15: - | T15: - | U15: - | V15: - | W15: - | X15: - | Y15: - | Z15: - | AA15: - | AB15: - | AC15: - | AF15: - | AH15: 11.5 | AI15: 15.6
A16: Lindsay | B16: 36 | C16: 5 | D16: 37 | E16: 5 | F16: 32 | G16: 4 | H16: 35 | I16: 5 | J16: 34 | K16: 5.5 | L16: 34 | M16: 2.5 | N16: 27 | P16: Lindsay | Q16: 4 | R16: - | S16: - | T16: 10.7 | U16: - | V16: - | W16: 9.5 | X16: 9.9 | Y16: - | Z16: - | AA16: 20 | AB16: 8.2 | AC16: - | AF16: - | AI16: -
A17: Lance | B17: 40 | C17: 2 | D17: 39 | E17: 4 | F17: 38 | G17: 3 | H17: 38 | I17: 2 | J17: 34 | K17: 5.5 | L17: 34 | M17: 2.5 | N17: 19 | P17: Lance | Q17: 0 | R17: - | S17: - | T17: - | U17: - | V17: - | W17: - | X17: - | Y17: - | Z17: - | AA17: - | AB17: - | AC17: - | AF17: - | AH17: 17.7 | AI17: -
A18: Shea | B18: 31.5 | C18: 7 | D18: 29.5 | E18: 8 | F18: 25.5 | G18: 8 | H18: 28.5 | I18: 8 | J18: -12.5 | K18: 1 | L18: 28.5 | M18: 8 | N18: 40 | P18: Shea | Q18: 8 | R18: - | S18: - | T18: 7.8 | U18: 20.6 | V18: - | W18: - | X18: - | Y18: 6.3 | Z18: 8 | AA18: 4.2 | AB18: - | AC18: - | AF18: 11.9 | AH18: 6.1 | AI18: 12.9
A19: Tim | B19: 30 | C19: 8 | D19: 33 | E19: 7 | F19: 30 | G19: 5 | H19: 34 | I19: 7 | J19: -12 | K19: 1 | L19: 32 | M19: 5 | N19: 33 | P19: Tim | Q19: 2 | R19: 17.9 | S19: - | T19: 11.7 | U19: - | V19: - | W19: - | X19: - | Y19: 8.3 | Z19: 12 | AA19: - | AB19: 8.8 | AC19: 10.9 | AF19: - | AH19: - | AI19: -
A20: Sonat | B20: 36.5 | C20: 4 | D20: 33.5 | E20: 6 | F20: 26.5 | G20: 7 | H20: 37.5 | I20: 4 | J20: 30.5 | K20: 7 | L20: 32.5 | M20: 4 | N20: 32 | P20: Sonat | Q20: 3 | R20: - | S20: - | T20: - | U20: - | V20: winner | W20: - | X20: 21.3 | Y20: 8.7 | Z20: - | AA20: - | AB20: 4.6 | AC20: - | AF20: 13.2 | AH20: 0,9 | AI20: -
A21: Jeremy | B21: -23 | C21: 1 | D21: 39 | E21: 3 | F21: 29 | G21: 6 | H21: 38 | I21: 3 | J21: 46 | K21: 4 | L21: 31 | M21: 6 | N21: 23 | P21: Jeremy | Q21: 0 | R21: - | S21: - | T21: - | U21: - | V21: - | W21: - | X21: - | Y21: - | Z21: - | AA21: - | AB21: - | AC21: - | AF21: - | AH21: - | AI21: -
A23: Tournament 2
A24: Player | B24: Week 1 | C24: Points | D24: Week 2 | E24: Points | F24: Week 3 | G24: Points | H24: Week 4 | I24: Points | J24: Week 5 | K24: Points | L24: Week 6 | M24: Points | N24: Total
A25: Cody | B25: 40 | C25: 2.5 | D25: 39 | E25: 3 | F25: 31 | G25: 5.5 | H25: 36 | I25: 3.5 | J25: 34 | K25: 5 | L25: 37 | M25: 6 | N25: {=C25+E25+G25+I25+K25+M25} -> 25.5
A26: Jordan | B26: 35 | C26: 6 | D26: 27 | E26: 8 | F26: 37 | G26: 3 | H26: 33 | I26: 6.5 | J26: -14 | K26: 1 | L26: -14 | M26: 1 | N26: {=C26+E26+G26+I26+K26+M26} -> 25.5
A27: Lindsay | B27: 40 | C27: 2.5 | D27: -6 | E27: 1 | F27: -6 | G27: 1 | H27: 41 | I27: 1 | J27: 39 | K27: 3 | L27: -6 | M27: 1 | N27: {=C27+E27+G27+I27+K27+M27} -> 9.5
A28: Lance | B28: 27 | C28: 8 | D28: 29 | E28: 7 | F28: -24 | G28: 1 | H28: 26 | I28: 8 | J28: -24 | K28: 1 | L28: -24 | M28: 1 | N28: {=C28+E28+G28+I28+K28+M28} -> 26
A29: Shea | B29: 37 | C29: 4 | D29: 32 | E29: 6 | F29: 30 | G29: 7 | H29: 33 | I29: 6.5 | J29: 37 | K29: 4 | L29: 39 | M29: 5 | N29: {=C29+E29+G29+I29+K29+M29} -> 32.5
A30: Tim | B30: 29 | C30: 7 | D30: 33 | E30: 4.5 | F30: 32 | G30: 4 | H30: 37 | I30: 2 | J30: 31 | K30: 6 | L30: 33 | M30: 8 | N30: {=C30+E30+G30+I30+K30+M30} -> 31.5
A31: Sonat | B31: 36 | C31: 5 | D31: 33 | E31: 4.5 | F31: 31 | G31: 5.5 | H31: 36 | I31: 3.5 | J31: 29 | K31: 8 | L31: 42 | M31: 4 | N31: {=C31+E31+G31+I31+K31+M31} -> 30.5
A32: Jeremy | B32: -25 | C32: 1 | D32: 48 | E32: 2 | F32: 29 | G32: 8 | H32: 35 | I32: 5 | J32: 30 | K32: 7 | L32: 34 | M32: 7 | N32: {=C32+E32+G32+I32+K32+M32} -> 30
A34: Tournament 3
A35: Player | B35: Week 1 | C35: Points | D35: Week 2 | E35: Points | F35: Week 3 | G35: Points | H35: Week 4 | I35: Points | J35: Week 5 | K35: Points | L35: Week 6 | M35: Points | N35: Total
A36: Cody | B36: 49.708333 | C36: 2 | D36: 38.708333 | E36: 3 | F36: 34.708333 | G36: 6 | H36: 47.708333 | I36: 3 | J36: 29.708333 | K36: 6 | L36: 34.708333 | M36: 4.5 | N36: {=C36+E36+G36+I36+K36+M36} -> 24.5
A37: Jordan | B37: 43.325 | C37: 4 | D37: 31.325 | E37: 7 | F37: 46.325 | G37: 1 | H37: 50.325 | I37: 1.5 | J37: 31.325 | K37: 5 | L37: 36.325 | M37: 3 | N37: {=C37+E37+G37+I37+K37+M37} -> 21.5
A38: Lindsay | B38: 36.534091 | C38: 6 | D38: 35.534091 | E38: 4.5 | F38: 35.534091 | G38: 5 | H38: 40.534091 | I38: 5 | J38: -7.4659091 | K38: 1 | L38: -7.4659091 | M38: 1 | N38: {=C38+E38+G38+I38+K38+M38} -> 22.5
A39: Lance | B39: 36.443182 | C39: 7 | D39: 53.443182 | E39: 2 | F39: 31.443182 | G39: 7 | H39: 50.443182 | I39: 1.5 | J39: 34.443182 | K39: 3 | L39: 35.443182 | M39: 4.5 | N39: {=C39+E39+G39+I39+K39+M39} -> 25
A40: Shea | B40: -7.375 | C40: 1 | D40: -7.375 | E40: 1 | F40: 36.625 | G40: 4 | H40: 38.625 | I40: 6 | J40: 31.625 | K40: 4 | L40: 37.625 | M40: 2 | N40: {=C40+E40+G40+I40+K40+M40} -> 18
A41: Tim | B41: 35.240385 | C41: 8 | D41: 36.240385 | E41: 4.5 | F41: 40.240385 | G41: 2 | H41: 37.240385 | I41: 8 | J41: 36.240385 | K41: 2 | L41: 31.240385 | M41: 7 | N41: {=C41+E41+G41+I41+K41+M41} -> 31.5
A42: Sonat | B42: 38.767857 | C42: 5 | D42: 34.767857 | E42: 6 | F42: 38.767857 | G42: 3 | H42: 41.767857 | I42: 4 | J42: 26.767857 | K42: 7.5 | L42: 31.767857 | M42: 6 | N42: {=C42+E42+G42+I42+K42+M42} -> 31.5
A43: Jeremy | B43: 47.041667 | C43: 3 | D43: 27.041667 | E43: 8 | F43: 30.041667 | G43: 8 | H43: 38.041667 | I43: 7 | J43: 27.041667 | K43: 7.5 | L43: 28.041667 | M43: 8 | N43: {=C43+E43+G43+I43+K43+M43} -> 41.5

Sheet Tournament 1 - PivotTable3
A1: PivotTable3
A2: Player | B2: Total (Sum)
A3: Shea | B3: 40
A4: Tim | B4: 33
A5: Sonat | B5: 32
A6: Lindsay | B6: 27
A7: Cody | B7: 26
A8: Jeremy | B8: 23
A9: Lance | B9: 19
A10: Jordan | B10: 15
A11: Grand Total | B11: 215

Sheet Tournament 1 - Table 1
A12: Tournament 1 | P12: Points | R12: *split points if tied* | T12: Closest Too
A13: Player | B13: Week 1 | C13: Points | D13: Week 2 | E13: Points | F13: Week 3 | G13: Points | H13: Week 4 | I13: Points | J13: Week 5 | K13: Points | L13: Week 6 | M13: Points | N13: Total | P13: 1st | Q13: 8 | T13: Player | U13: Week 1 | V13: Week 2 | W13: Week 3 | X13: Week 4 | Y13: Week 5 | Z13: Week 6
A14: Cody | B14: {=M26} -> 38.5 | C14: 3 | D14: {=Y26} -> -25.5 | E14: 1 | F14: {=M39} -> -25.5 | G14: 1 | H14: {=Y39} -> 34.5 | I14: 6 | J14: {=M52} -> 27.5 | K14: 8 | L14: {=Y52} -> 30.5 | M14: 7 | N14: {=C14+E14+G14+I14+K14+M14} -> 26 | P14: 2nd | Q14: 7 | T14: Cody | U14: - | V14: - | W14: - | X14: - | Y14: - | Z14: -
A15: Jordan | B15: {=M27} -> 32.5 | C15: 6 | D15: {=Y27} -> 41.5 | E15: 2 | F15: {=M40} -> 38.5 | G15: 2 | H15: {=Y40} -> -10.5 | I15: 1 | J15: {=M53} -> 47.5 | K15: 3 | L15: {=Y53} -> -10.5 | M15: 1 | N15: {=C15+E15+G15+I15+K15+M15} -> 15 | P15: 3rd | Q15: 6 | T15: Jordan | U15: 6.5 | V15: - | W15: - | X15: - | Y15: - | Z15: -
A16: Lindsay | B16: {=M28} -> 36 | C16: 5 | D16: {=Y28} -> 37 | E16: 5 | F16: {=M41} -> 32 | G16: 4 | H16: {=Y41} -> 35 | I16: 5 | J16: {=M54} -> 34 | K16: 5.5 | L16: {=Y54} -> 34 | M16: 2.5 | N16: {=C16+E16+G16+I16+K16+M16} -> 27 | P16: 4th | Q16: 5 | T16: Lindsay | U16: - | V16: - | W16: 10.7 | X16: - | Y16: - | Z16: 9.5
A17: Lance | B17: {=M29} -> 40 | C17: 2 | D17: {=Y29} -> 39 | E17: 4 | F17: {=M42} -> 38 | G17: 3 | H17: {=Y42} -> 38 | I17: 2 | J17: {=M55} -> 34 | K17: 5.5 | L17: {=Y55} -> 34 | M17: 2.5 | N17: {=C17+E17+G17+I17+K17+M17} -> 19 | P17: 5th | Q17: 4 | T17: Lance | U17: - | V17: - | W17: - | X17: - | Y17: - | Z17: -
A18: Shea | B18: {=M30} -> 31.5 | C18: 7 | D18: {=Y30} -> 29.5 | E18: 8 | F18: {=M43} -> 25.5 | G18: 8 | H18: {=Y43} -> 28.5 | I18: 8 | J18: {=M56} -> -12.5 | K18: 1 | L18: {=Y56} -> 28.5 | M18: 8 | N18: {=C18+E18+G18+I18+K18+M18} -> 40 | P18: 6th | Q18: 3 | T18: Shea | U18: - | V18: - | W18: 7.8 | X18: 20.6 | Y18: - | Z18: -
A19: Tim | B19: {=M31} -> 30 | C19: 8 | D19: {=Y31} -> 33 | E19: 7 | F19: {=M44} -> 30 | G19: 5 | H19: {=Y44} -> 34 | I19: 7 | J19: {=M57} -> -12 | K19: 1 | L19: {=Y57} -> 32 | M19: 5 | N19: {=C19+E19+G19+I19+K19+M19} -> 33 | P19: 7th | Q19: 2 | T19: Tim | U19: 17.9 | V19: - | W19: 11.7 | X19: - | Y19: - | Z19: -
A20: Sonat | B20: {=M32} -> 36.5 | C20: 4 | D20: {=Y32} -> 33.5 | E20: 6 | F20: {=M45} -> 26.5 | G20: 7 | H20: {=Y45} -> 37.5 | I20: 4 | J20: {=M58} -> 30.5 | K20: 7 | L20: {=Y58} -> 32.5 | M20: 4 | N20: {=C20+E20+G20+I20+K20+M20} -> 32 | P20: 8th | Q20: 1 | T20: Sonat | U20: - | V20: - | W20: - | X20: - | Y20: winner | Z20: -
A21: Jeremy | B21: {=M33} -> -23 | C21: 1 | D21: {=Y33} -> 39 | E21: 3 | F21: {=M46} -> 29 | G21: 6 | H21: {=Y46} -> 38 | I21: 3 | J21: {=M59} -> 46 | K21: 4 | L21: {=Y59} -> 31 | M21: 6 | N21: {=C21+E21+G21+I21+K21+M21} -> 23 | T21: Jeremy | U21: - | V21: - | W21: - | X21: - | Y21: - | Z21: -
A23: Grove XXIII | B23: 1 | C23: 2 | D23: 3 | E23: 4 | F23: 5 | G23: 6 | H23: 7 | I23: 8 | J23: 9 | K23: Total | L23: Handicap | M23: Score | N23: 10 | O23: 11 | P23: 12 | Q23: 13 | R23: 14 | S23: 15 | T23: 16 | U23: 17 | V23: 18 | W23: Total | X23: Handicap | Y23: Score
A24: Par | B24: 4 | C24: 4 | D24: 3 | E24: 5 | F24: 4 | G24: 4 | H24: 3 | I24: 5 | J24: 4 | K24: {=SUM(B24:J24)} -> 36 | N24: 4 | O24: 5 | P24: 4 | Q24: 3 | R24: 4 | S24: 3 | T24: 4 | U24: 5 | V24: 4 | W24: {=SUM(N24:V24)} -> 36
A25: Player
A26: Cody | B26: 5 | C26: 7 | D26: 4 | E26: 8 | F26: 6 | G26: 7 | H26: 4 | I26: 12 | J26: 11 | K26: {=SUM(B26:J26)} -> 64 | L26: 25.5 | M26: {=K26-L26} -> 38.5 | W26: {=SUM(N26:V26)} -> 0 | X26: 25.5 | Y26: {=W26-X26} -> -25.5
A27: Jordan | B27: 4 | C27: 4 | D27: 6 | E27: 6 | F27: 5 | G27: 5 | H27: 3 | I27: 6 | J27: 4 | K27: {=SUM(B27:J27)} -> 43 | L27: 10.5 | M27: {=K27-L27} -> 32.5 | N27: 6 | O27: 6 | P27: 6 | Q27: 5 | R27: 7 | S27: 5 | T27: 5 | U27: 6 | V27: 6 | W27: {=SUM(N27:V27)} -> 52 | X27: 10.5 | Y27: {=W27-X27} -> 41.5
A28: Lindsay | B28: 5 | C28: 5 | D28: 4 | E28: 5 | F28: 4 | G28: 3 | H28: 4 | I28: 9 | J28: 4 | K28: {=SUM(B28:J28)} -> 43 | L28: 7 | M28: {=K28-L28} -> 36 | N28: 4 | O28: 7 | P28: 5 | Q28: 3 | R28: 5 | S28: 3 | T28: 6 | U28: 7 | V28: 4 | W28: {=SUM(N28:V28)} -> 44 | X28: 7 | Y28: {=W28-X28} -> 37
A29: Lance | B29: 7 | C29: 5 | D29: 6 | E29: 9 | F29: 6 | G29: 8 | H29: 5 | I29: 10 | J29: 6 | K29: {=SUM(B29:J29)} -> 62 | L29: 22 | M29: {=K29-L29} -> 40 | N29: 6 | O29: 7 | P29: 6 | Q29: 5 | R29: 8 | S29: 8 | T29: 8 | U29: 7 | V29: 6 | W29: {=SUM(N29:V29)} -> 61 | X29: 22 | Y29: {=W29-X29} -> 39
A30: Shea | B30: 5 | C30: 4 | D30: 3 | E30: 6 | F30: 3 | G30: 9 | H30: 4 | I30: 5 | J30: 5 | K30: {=SUM(B30:J30)} -> 44 | L30: 12.5 | M30: {=K30-L30} -> 31.5 | N30: 4 | O30: 6 | P30: 5 | Q30: 4 | R30: 5 | S30: 3 | T30: 4 | U30: 6 | V30: 5 | W30: {=SUM(N30:V30)} -> 42 | X30: 12.5 | Y30: {=W30-X30} -> 29.5
A31: Tim | B31: 6 | C31: 5 | D31: 4 | E31: 5 | F31: 4 | G31: 5 | H31: 4 | I31: 5 | J31: 4 | K31: {=SUM(B31:J31)} -> 42 | L31: 12 | M31: {=K31-L31} -> 30 | N31: 4 | O31: 7 | P31: 5 | Q31: 3 | R31: 7 | S31: 4 | T31: 4 | U31: 6 | V31: 5 | W31: {=SUM(N31:V31)} -> 45 | X31: 12 | Y31: {=W31-X31} -> 33
A32: Sonat | B32: 5 | C32: 5 | D32: 5 | E32: 7 | F32: 5 | G32: 5 | H32: 5 | I32: 7 | J32: 5 | K32: {=SUM(B32:J32)} -> 49 | L32: 12.5 | M32: {=K32-L32} -> 36.5 | N32: 6 | O32: 5 | P32: 5 | Q32: 5 | R32: 6 | S32: 4 | T32: 4 | U32: 5 | V32: 6 | W32: {=SUM(N32:V32)} -> 46 | X32: 12.5 | Y32: {=W32-X32} -> 33.5
A33: Jeremy | K33: {=SUM(B33:J33)} -> 0 | L33: 23 | M33: {=K33-L33} -> -23 | N33: 6 | O33: 8 | P33: 7 | Q33: 6 | R33: 8 | S33: 4 | T33: 8 | U33: 7 | V33: 8 | W33: {=SUM(N33:V33)} -> 62 | X33: 23 | Y33: {=W33-X33} -> 39
D34: 210 yrd | H34: 155 yrd | Q34: 193 yrd | S34: 126 yrd
A36: TPC Scottdale | B36: 1 | C36: 2 | D36: 3 | E36: 4 | F36: 5 | G36: 6 | H36: 7 | I36: 8 | J36: 9 | K36: Total | L36: Handicap | M36: Score | N36: 10 | O36: 11 | P36: 12 | Q36: 13 | R36: 14 | S36: 15 | T36: 16 | U36: 17 | V36: 18 | W36: Total | X36: Handicap | Y36: Score
A37: Par | B37: 4 | C37: 4 | D37: 5 | E37: 3 | F37: 4 | G37: 4 | H37: 3 | I37: 4 | J37: 4 | K37: {=SUM(B37:J37)} -> 35 | N37: 4 | O37: 4 | P37: 3 | Q37: 5 | R37: 4 | S37: 5 | T37: 3 | U37: 4 | V37: 4 | W37: {=SUM(N37:V37)} -> 36
A38: Player
A39: Cody | K39: {=SUM(B39:J39)} -> 0 | L39: 25.5 | M39: {=K39-L39} -> -25.5 | N39: 5 | O39: 6 | P39: 5 | Q39: 8 | R39: 9 | S39: 9 | T39: 3 | U39: 5 | V39: 10 | W39: {=SUM(N39:V39)} -> 60 | X39: 25.5 | Y39: {=W39-X39} -> 34.5
A40: Jordan | B40: 5 | C40: 6 | D40: 7 | E40: 6 | F40: 4 | G40: 6 | H40: 5 | I40: 5 | J40: 5 | K40: {=SUM(B40:J40)} -> 49 | L40: 10.5 | M40: {=K40-L40} -> 38.5 | W40: {=SUM(N40:V40)} -> 0 | X40: 10.5 | Y40: {=W40-X40} -> -10.5
A41: Lindsay | B41: 5 | C41: 5 | D41: 6 | E41: 3 | F41: 4 | G41: 4 | H41: 3 | I41: 4 | J41: 5 | K41: {=SUM(B41:J41)} -> 39 | L41: 7 | M41: {=K41-L41} -> 32 | N41: 4 | O41: 5 | P41: 3 | Q41: 5 | R41: 6 | S41: 5 | T41: 4 | U41: 6 | V41: 4 | W41: {=SUM(N41:V41)} -> 42 | X41: 7 | Y41: {=W41-X41} -> 35
A42: Lance | B42: 10 | C42: 5 | D42: 8 | E42: 5 | F42: 7 | G42: 6 | H42: 4 | I42: 6 | J42: 9 | K42: {=SUM(B42:J42)} -> 60 | L42: 22 | M42: {=K42-L42} -> 38 | N42: 5 | O42: 7 | P42: 3 | Q42: 7 | R42: 9 | S42: 8 | T42: 5 | U42: 10 | V42: 6 | W42: {=SUM(N42:V42)} -> 60 | X42: 22 | Y42: {=W42-X42} -> 38
A43: Shea | B43: 4 | C43: 5 | D43: 6 | E43: 3 | F43: 5 | G43: 4 | H43: 3 | I43: 3 | J43: 5 | K43: {=SUM(B43:J43)} -> 38 | L43: 12.5 | M43: {=K43-L43} -> 25.5 | N43: 4 | O43: 6 | P43: 4 | Q43: 5 | R43: 6 | S43: 4 | T43: 4 | U43: 4 | V43: 4 | W43: {=SUM(N43:V43)} -> 41 | X43: 12.5 | Y43: {=W43-X43} -> 28.5
A44: Tim | B44: 7 | C44: 5 | D44: 5 | E44: 3 | F44: 4 | G44: 4 | H44: 4 | I44: 5 | J44: 5 | K44: {=SUM(B44:J44)} -> 42 | L44: 12 | M44: {=K44-L44} -> 30 | N44: 5 | O44: 5 | P44: 5 | Q44: 5 | R44: 5 | S44: 6 | T44: 3 | U44: 4 | V44: 8 | W44: {=SUM(N44:V44)} -> 46 | X44: 12 | Y44: {=W44-X44} -> 34
A45: Sonat | B45: 4 | C45: 4 | D45: 6 | E45: 4 | F45: 4 | G45: 4 | H45: 3 | I45: 5 | J45: 5 | K45: {=SUM(B45:J45)} -> 39 | L45: 12.5 | M45: {=K45-L45} -> 26.5 | N45: 5 | O45: 5 | P45: 6 | Q45: 5 | R45: 5 | S45: 8 | T45: 5 | U45: 5 | V45: 6 | W45: {=SUM(N45:V45)} -> 50 | X45: 12.5 | Y45: {=W45-X45} -> 37.5
A46: Jeremy | B46: 8 | C46: 5 | D46: 8 | E46: 4 | F46: 6 | G46: 4 | H46: 3 | I46: 7 | J46: 7 | K46: {=SUM(B46:J46)} -> 52 | L46: 23 | M46: {=K46-L46} -> 29 | N46: 6 | O46: 6 | P46: 4 | Q46: 9 | R46: 7 | S46: 10 | T46: 5 | U46: 8 | V46: 6 | W46: {=SUM(N46:V46)} -> 61 | X46: 23 | Y46: {=W46-X46} -> 38
E47: 147 yrd | T47: 114 yrd
A49: Wynn | B49: 1 | C49: 2 | D49: 3 | E49: 4 | F49: 5 | G49: 6 | H49: 7 | I49: 8 | J49: 9 | K49: Total | L49: Handicap | M49: Score | N49: 10 | O49: 11 | P49: 12 | Q49: 13 | R49: 14 | S49: 15 | T49: 16 | U49: 17 | V49: 18 | W49: Total | X49: Handicap | Y49: Score
A50: Par | B50: 4 | C50: 3 | D50: 5 | E50: 4 | F50: 3 | G50: 4 | H50: 3 | I50: 5 | J50: 4 | K50: {=SUM(B50:J50)} -> 35 | N50: 3 | O50: 5 | P50: 3 | Q50: 5 | R50: 4 | S50: 4 | T50: 4 | U50: 4 | V50: 3 | W50: {=SUM(N50:V50)} -> 35
A51: Player
A52: Cody | B52: 5 | C52: 5 | D52: 8 | E52: 5 | F52: 4 | G52: 5 | H52: 4 | I52: 9 | J52: 8 | K52: {=SUM(B52:J52)} -> 53 | L52: 25.5 | M52: {=K52-L52} -> 27.5 | N52: 4 | O52: 10 | P52: 3 | Q52: 8 | R52: 7 | S52: 5 | T52: 8 | U52: 6 | V52: 5 | W52: {=SUM(N52:V52)} -> 56 | X52: 25.5 | Y52: {=W52-X52} -> 30.5
A53: Jordan | B53: 4 | C53: 6 | D53: 8 | E53: 6 | F53: 4 | G53: 7 | H53: 5 | I53: 13 | J53: 5 | K53: {=SUM(B53:J53)} -> 58 | L53: 10.5 | M53: {=K53-L53} -> 47.5 | W53: {=SUM(N53:V53)} -> 0 | X53: 10.5 | Y53: {=W53-X53} -> -10.5
A54: Lindsay | B54: 4 | C54: 4 | D54: 6 | E54: 4 | F54: 4 | G54: 5 | H54: 3 | I54: 6 | J54: 5 | K54: {=SUM(B54:J54)} -> 41 | L54: 7 | M54: {=K54-L54} -> 34 | N54: 4 | O54: 9 | P54: 3 | Q54: 5 | R54: 4 | S54: 4 | T54: 5 | U54: 5 | V54: 2 | W54: {=SUM(N54:V54)} -> 41 | X54: 7 | Y54: {=W54-X54} -> 34
...

Sheet Tournament 2 - PivotTable4
A1: PivotTable4
A2: Player | B2: Total (Sum)
A3: Shea | B3: 32.5
A4: Tim | B4: 31.5
A5: Sonat | B5: 30.5
A6: Jeremy | B6: 30
A7: Lance | B7: 26
A8: Cody | B8: 25.5
A9: Jordan | B9: 25.5
A10: Lindsay | B10: 9.5
A11: Grand Total | B11: 211

Sheet Tournament 2 - Table 1
A12: Tournament 2 | P12: Points | R12: *split points if tied* | T12: Closest Too
A13: Player | B13: Week 1 | C13: Points | D13: Week 2 | E13: Points | F13: Week 3 | G13: Points | H13: Week 4 | I13: Points | J13: Week 5 | K13: Points | L13: Week 6 | M13: Points | N13: Total | P13: 1st | Q13: 8 | T13: Player | U13: Week 1 | V13: Week 2 | W13: Week 3 | X13: Week 4 | Y13: Week 5 | Z13: Week 6
A14: Cody | B14: {=M26} -> 40 | C14: 2.5 | D14: {=Y26} -> 39 | E14: 3 | F14: {=M39} -> 31 | G14: 5.5 | H14: {=Y39} -> 36 | I14: 3.5 | J14: {=M52} -> 34 | K14: 5 | L14: {=Y52} -> 37 | M14: 6 | N14: {=C14+E14+G14+I14+K14+M14} -> 25.5 | P14: 2nd | Q14: 7 | T14: Cody | U14: - | V14: - | W14: - | X14: - | Y14: - | Z14: -
A15: Jordan | B15: {=M27} -> 35 | C15: 6 | D15: {=Y27} -> 27 | E15: 8 | F15: {=M40} -> 37 | G15: 3 | H15: {=Y40} -> 33 | I15: 6.5 | J15: {=M53} -> -14 | K15: 1 | L15: {=Y53} -> -14 | M15: 1 | N15: {=C15+E15+G15+I15+K15+M15} -> 25.5 | P15: 3rd | Q15: 6 | T15: Jordan | U15: - | V15: - | W15: - | X15: - | Y15: - | Z15: -
A16: Lindsay | B16: {=M28} -> 40 | C16: 2.5 | D16: {=Y28} -> -6 | E16: 1 | F16: {=M41} -> -6 | G16: 1 | H16: {=Y41} -> 41 | I16: 1 | J16: {=M54} -> 39 | K16: 3 | L16: {=Y54} -> -6 | M16: 1 | N16: {=C16+E16+G16+I16+K16+M16} -> 9.5 | P16: 4th | Q16: 5 | T16: Lindsay | U16: 9.9 | V16: - | W16: - | X16: 20 | Y16: 8.2 | Z16: -
A17: Lance | B17: {=M29} -> 27 | C17: 8 | D17: {=Y29} -> 29 | E17: 7 | F17: {=M42} -> -24 | G17: 1 | H17: {=Y42} -> 26 | I17: 8 | J17: {=M55} -> -24 | K17: 1 | L17: {=Y55} -> -24 | M17: 1 | N17: {=C17+E17+G17+I17+K17+M17} -> 26 | P17: 5th | Q17: 4 | T17: Lance | U17: - | V17: - | W17: - | X17: - | Y17: - | Z17: -
A18: Shea | B18: {=M30} -> 37 | C18: 4 | D18: {=Y30} -> 32 | E18: 6 | F18: {=M43} -> 30 | G18: 7 | H18: {=Y43} -> 33 | I18: 6.5 | J18: {=M56} -> 37 | K18: 4 | L18: {=Y56} -> 39 | M18: 5 | N18: {=C18+E18+G18+I18+K18+M18} -> 32.5 | P18: 6th | Q18: 3 | T18: Shea | U18: - | V18: 6.3 | W18: 8 | X18: 4.2 | Y18: - | Z18: -
A19: Tim | B19: {=M31} -> 29 | C19: 7 | D19: {=Y31} -> 33 | E19: 4.5 | F19: {=M44} -> 32 | G19: 4 | H19: {=Y44} -> 37 | I19: 2 | J19: {=M57} -> 31 | K19: 6 | L19: {=Y57} -> 33 | M19: 8 | N19: {=C19+E19+G19+I19+K19+M19} -> 31.5 | P19: 7th | Q19: 2 | T19: Tim | U19: - | V19: 8.3 | W19: 12 | X19: - | Y19: 8.8 | Z19: 10.9
A20: Sonat | B20: {=M32} -> 36 | C20: 5 | D20: {=Y32} -> 33 | E20: 4.5 | F20: {=M45} -> 31 | G20: 5.5 | H20: {=Y45} -> 36 | I20: 3.5 | J20: {=M58} -> 29 | K20: 8 | L20: {=Y58} -> 42 | M20: 4 | N20: {=C20+E20+G20+I20+K20+M20} -> 30.5 | P20: 8th | Q20: 1 | T20: Sonat | U20: 21.3 | V20: 8.7 | W20: - | X20: - | Y20: 4.6 | Z20: -
A21: Jeremy | B21: {=M33} -> -25 | C21: 1 | D21: {=Y33} -> 48 | E21: 2 | F21: {=M46} -> 29 | G21: 8 | H21: {=Y46} -> 35 | I21: 5 | J21: {=M59} -> 30 | K21: 7 | L21: {=Y59} -> 34 | M21: 7 | N21: {=C21+E21+G21+I21+K21+M21} -> 30 | T21: Jeremy | U21: - | V21: - | W21: - | X21: - | Y21: - | Z21: -
A23: Cypress Point | B23: 1 | C23: 2 | D23: 3 | E23: 4 | F23: 5 | G23: 6 | H23: 7 | I23: 8 | J23: 9 | K23: Total | L23: Handicap | M23: Score | N23: 10 | O23: 11 | P23: 12 | Q23: 13 | R23: 14 | S23: 15 | T23: 16 | U23: 17 | V23: 18 | W23: Total | X23: Handicap | Y23: Score
A24: Par | B24: 4 | C24: 5 | D24: 3 | E24: 4 | F24: 5 | G24: 5 | H24: 3 | I24: 4 | J24: 4 | K24: {=SUM(B24:J24)} -> 37 | N24: 5 | O24: 4 | P24: 4 | Q24: 4 | R24: 4 | S24: 3 | T24: 3 | U24: 4 | V24: 4 | W24: {=SUM(N24:V24)} -> 35
A25: Player
A26: Cody | B26: 6 | C26: 9 | D26: 6 | E26: 7 | F26: 7 | G26: 9 | H26: 5 | I26: 9 | J26: 6 | K26: {=SUM(B26:J26)} -> 64 | L26: 24 | M26: {=K26-L26} -> 40 | N26: 9 | O26: 6 | P26: 5 | Q26: 7 | R26: 7 | S26: 6 | T26: 10 | U26: 7 | V26: 6 | W26: {=SUM(N26:V26)} -> 63 | X26: 24 | Y26: {=W26-X26} -> 39
A27: Jordan | B27: 5 | C27: 5 | D27: 4 | E27: 7 | F27: 7 | G27: 6 | H27: 4 | I27: 5 | J27: 6 | K27: {=SUM(B27:J27)} -> 49 | L27: 14 | M27: {=K27-L27} -> 35 | N27: 5 | O27: 6 | P27: 4 | Q27: 6 | R27: 4 | S27: 4 | T27: 3 | U27: 5 | V27: 4 | W27: {=SUM(N27:V27)} -> 41 | X27: 14 | Y27: {=W27-X27} -> 27
A28: Lindsay | B28: 5 | C28: 6 | D28: 4 | E28: 5 | F28: 5 | G28: 9 | H28: 3 | I28: 4 | J28: 5 | K28: {=SUM(B28:J28)} -> 46 | L28: 6 | M28: {=K28-L28} -> 40 | W28: {=SUM(N28:V28)} -> 0 | X28: 6 | Y28: {=W28-X28} -> -6
A29: Lance | B29: 5 | C29: 7 | D29: 4 | E29: 5 | F29: 6 | G29: 6 | H29: 5 | I29: 6 | J29: 7 | K29: {=SUM(B29:J29)} -> 51 | L29: 24 | M29: {=K29-L29} -> 27 | N29: 6 | O29: 7 | P29: 5 | Q29: 7 | R29: 6 | S29: 4 | T29: 4 | U29: 8 | V29: 6 | W29: {=SUM(N29:V29)} -> 53 | X29: 24 | Y29: {=W29-X29} -> 29
A30: Shea | B30: 5 | C30: 8 | D30: 4 | E30: 4 | F30: 6 | G30: 6 | H30: 3 | I30: 5 | J30: 4 | K30: {=SUM(B30:J30)} -> 45 | L30: 8 | M30: {=K30-L30} -> 37 | N30: 5 | O30: 6 | P30: 5 | Q30: 5 | R30: 4 | S30: 3 | T30: 4 | U30: 4 | V30: 4 | W30: {=SUM(N30:V30)} -> 40 | X30: 8 | Y30: {=W30-X30} -> 32
A31: Tim | B31: 3 | C31: 6 | D31: 3 | E31: 4 | F31: 6 | G31: 7 | H31: 2 | I31: 3 | J31: 4 | K31: {=SUM(B31:J31)} -> 38 | L31: 9 | M31: {=K31-L31} -> 29 | N31: 6 | O31: 7 | P31: 5 | Q31: 3 | R31: 3 | S31: 3 | T31: 6 | U31: 5 | V31: 4 | W31: {=SUM(N31:V31)} -> 42 | X31: 9 | Y31: {=W31-X31} -> 33
A32: Sonat | B32: 7 | C32: 7 | D32: 3 | E32: 6 | F32: 6 | G32: 6 | H32: 3 | I32: 5 | J32: 4 | K32: {=SUM(B32:J32)} -> 47 | L32: 11 | M32: {=K32-L32} -> 36 | N32: 6 | O32: 5 | P32: 4 | Q32: 5 | R32: 6 | S32: 4 | T32: 4 | U32: 5 | V32: 5 | W32: {=SUM(N32:V32)} -> 44 | X32: 11 | Y32: {=W32-X32} -> 33
A33: Jeremy | K33: {=SUM(B33:J33)} -> 0 | L33: 25 | M33: {=K33-L33} -> -25 | N33: 12 | O33: 8 | P33: 5 | Q33: 6 | R33: 7 | S33: 5 | T33: 15 | U33: 8 | V33: 7 | W33: {=SUM(N33:V33)} -> 73 | X33: 25 | Y33: {=W33-X33} -> 48
D34: 156 yrd | H34: 166 yrd | S34: 121 yrd | T34: 217 yrd
A36: The Dunes | B36: 1 | C36: 2 | D36: 3 | E36: 4 | F36: 5 | G36: 6 | H36: 7 | I36: 8 | J36: 9 | K36: Total | L36: Handicap | M36: Score | N36: 10 | O36: 11 | P36: 12 | Q36: 13 | R36: 14 | S36: 15 | T36: 16 | U36: 17 | V36: 18 | W36: Total | X36: Handicap | Y36: Score
A37: Par | B37: 4 | C37: 4 | D37: 4 | E37: 5 | F37: 3 | G37: 4 | H37: 4 | I37: 5 | J37: 3 | K37: {=SUM(B37:J37)} -> 36 | N37: 4 | O37: 4 | P37: 3 | Q37: 5 | R37: 4 | S37: 5 | T37: 4 | U37: 3 | V37: 4 | W37: {=SUM(N37:V37)} -> 36
A38: Player
A39: Cody | B39: 5 | C39: 5 | D39: 8 | E39: 8 | F39: 4 | G39: 5 | H39: 4 | I39: 10 | J39: 6 | K39: {=SUM(B39:J39)} -> 55 | L39: 24 | M39: {=K39-L39} -> 31 | N39: 5 | O39: 5 | P39: 4 | Q39: 14 | R39: 6 | S39: 8 | T39: 5 | U39: 4 | V39: 9 | W39: {=SUM(N39:V39)} -> 60 | X39: 24 | Y39: {=W39-X39} -> 36
A40: Jordan | B40: 5 | C40: 7 | D40: 7 | E40: 8 | F40: 3 | G40: 5 | H40: 6 | I40: 6 | J40: 4 | K40: {=SUM(B40:J40)} -> 51 | L40: 14 | M40: {=K40-L40} -> 37 | N40: 5 | O40: 4 | P40: 5 | Q40: 8 | R40: 5 | S40: 6 | T40: 6 | U40: 3 | V40: 5 | W40: {=SUM(N40:V40)} -> 47 | X40: 14 | Y40: {=W40-X40} -> 33
A41: Lindsay | K41: {=SUM(B41:J41)} -> 0 | L41: 6 | M41: {=K41-L41} -> -6 | N41: 5 | O41: 4 | P41: 3 | Q41: 8 | R41: 3 | S41: 6 | T41: 4 | U41: 6 | V41: 8 | W41: {=SUM(N41:V41)} -> 47 | X41: 6 | Y41: {=W41-X41} -> 41
A42: Lance | K42: {=SUM(B42:J42)} -> 0 | L42: 24 | M42: {=K42-L42} -> -24 | N42: 5 | O42: 8 | P42: 4 | Q42: 7 | R42: 7 | S42: 5 | T42: 5 | U42: 4 | V42: 5 | W42: {=SUM(N42:V42)} -> 50 | X42: 24 | Y42: {=W42-X42} -> 26
A43: Shea | B43: 5 | C43: 5 | D43: 4 | E43: 4 | F43: 2 | G43: 4 | H43: 5 | I43: 7 | J43: 2 | K43: {=SUM(B43:J43)} -> 38 | L43: 8 | M43: {=K43-L43} -> 30 | N43: 4 | O43: 5 | P43: 3 | Q43: 6 | R43: 4 | S43: 6 | T43: 6 | U43: 3 | V43: 4 | W43: {=SUM(N43:V43)} -> 41 | X43: 8 | Y43: {=W43-X43} -> 33
A44: Tim | B44: 4 | C44: 5 | D44: 5 | E44: 3 | F44: 4 | G44: 5 | H44: 5 | I44: 6 | J44: 4 | K44: {=SUM(B44:J44)} -> 41 | L44: 9 | M44: {=K44-L44} -> 32 | N44: 5 | O44: 10 | P44: 3 | Q44: 5 | R44: 5 | S44: 5 | T44: 5 | U44: 3 | V44: 5 | W44: {=SUM(N44:V44)} -> 46 | X44: 9 | Y44: {=W44-X44} -> 37
A45: Sonat | B45: 4 | C45: 5 | D45: 4 | E45: 5 | F45: 5 | G45: 6 | H45: 5 | I45: 4 | J45: 4 | K45: {=SUM(B45:J45)} -> 42 | L45: 11 | M45: {=K45-L45} -> 31 | N45: 5 | O45: 5 | P45: 4 | Q45: 7 | R45: 5 | S45: 6 | T45: 5 | U45: 4 | V45: 6 | W45: {=SUM(N45:V45)} -> 47 | X45: 11 | Y45: {=W45-X45} -> 36
A46: Jeremy | B46: 6 | C46: 5 | D46: 7 | E46: 7 | F46: 4 | G46: 7 | H46: 5 | I46: 9 | J46: 4 | K46: {=SUM(B46:J46)} -> 54 | L46: 25 | M46: {=K46-L46} -> 29 | N46: 7 | O46: 5 | P46: 4 | Q46: 12 | R46: 8 | S46: 6 | T46: 7 | U46: 5 | V46: 6 | W46: {=SUM(N46:V46)} -> 60 | X46: 25 | Y46: {=W46-X46} -> 35
F47: 131 yrd | J47: 119 yrd | P47: 144 yrd | U47: 139 yrd
A49: Whisler Nickalaus | B49: 1 | C49: 2 | D49: 3 | E49: 4 | F49: 5 | G49: 6 | H49: 7 | I49: 8 | J49: 9 | K49: Total | L49: Handicap | M49: Score | N49: 10 | O49: 11 | P49: 12 | Q49: 13 | R49: 14 | S49: 15 | T49: 16 | U49: 17 | V49: 18 | W49: Total | X49: Handicap | Y49: Score
A50: Par | B50: 4 | C50: 3 | D50: 5 | E50: 4 | F50: 4 | G50: 3 | H50: 4 | I50: 5 | J50: 4 | K50: {=SUM(B50:J50)} -> 36 | N50: 3 | O50: 5 | P50: 3 | Q50: 5 | R50: 4 | S50: 4 | T50: 4 | U50: 3 | V50: 4 | W50: {=SUM(N50:V50)} -> 35
A51: Player
A52: Cody | B52: 5 | C52: 6 | D52: 7 | E52: 6 | F52: 8 | G52: 6 | H52: 5 | I52: 9 | J52: 6 | K52: {=SUM(B52:J52)} -> 58 | L52: 24 | M52: {=K52-L52} -> 34 | N52: 11 | O52: 11 | P52: 4 | Q52: 8 | R52: 5 | S52: 6 | T52: 5 | U52: 4 | V52: 7 | W52: {=SUM(N52:V52)} -> 61 | X52: 24 | Y52: {=W52-X52} -> 37
A53: Jordan | K53: {=SUM(B53:J53)} -> 0 | L53: 14 | M53: {=K53-L53} -> -14 | W53: {=SUM(N53:V53)} -> 0 | X53: 14 | Y53: {=W53-X53} -> -14
A54: Lindsay | B54: 9 | C54: 3 | D54: 8 | E54: 5 | F54: 4 | G54: 3 | H54: 4 | I54: 5 | J54: 4 | K54: {=SUM(B54:J54)} -> 45 | L54: 6 | M54: {=K54-L54} -> 39 | W54: {=SUM(N54:V54)} -> 0 | X54: 6 | Y54: {=W54-X54} -> -6
...

Sheet Tournament 3 - PivotTable4
A1: PivotTable4
A2: Player | B2: Total (Sum)
A3: Jeremy | B3: 41.5
A4: Tim | B4: 31.5
A5: Sonat | B5: 31.5
A6: Lance | B6: 25
A7: Cody | B7: 24.5
A8: Lindsay | B8: 22.5
A9: Jordan | B9: 21.5
A10: Shea | B10: 18
A11: Grand Total | B11: 216

Sheet Tournament 3 - Table 1
A12: Tournament 3 | P12: Points | R12: *split points if tied* | T12: Closest Too
A13: Player | B13: Week 1 | C13: Points | D13: Week 2 | E13: Points | F13: Week 3 | G13: Points | H13: Week 4 | I13: Points | J13: Week 5 | K13: Points | L13: Week 6 | M13: Points | N13: Total | P13: 1st | Q13: 8 | T13: Player | U13: Week 1 | V13: Week 2 | W13: Week 3 | X13: Week 4 | Y13: Week 5 | Z13: Week 6
A14: Cody | B14: {=M26} -> 49.708333 | C14: 2 | D14: {=Y26} -> 38.708333 | E14: 3 | F14: {=M39} -> 34.708333 | G14: 6 | H14: {=Y39} -> 47.708333 | I14: 3 | J14: 29.708333 | K14: 6 | L14: {=Y52} -> 34.708333 | M14: 4.5 | N14: {=C14+E14+G14+I14+K14+M14} -> 24.5 | P14: 2nd | Q14: 7 | T14: Cody | W14: - | Y14: - | Z14: -
A15: Jordan | B15: {=M27} -> 43.325 | C15: 4 | D15: {=Y27} -> 31.325 | E15: 7 | F15: {=M40} -> 46.325 | G15: 1 | H15: {=Y40} -> 50.325 | I15: 1.5 | J15: 31.325 | K15: 5 | L15: {=Y53} -> 36.325 | M15: 3 | N15: {=C15+E15+G15+I15+K15+M15} -> 21.5 | P15: 3rd | Q15: 6 | T15: Jordan | W15: - | Y15: 11.5 | Z15: 15.6
A16: Lindsay | B16: {=M28} -> 36.534091 | C16: 6 | D16: {=Y28} -> 35.534091 | E16: 4.5 | F16: {=M41} -> 35.534091 | G16: 5 | H16: {=Y41} -> 40.534091 | I16: 5 | J16: -7.4659091 | K16: 1 | L16: {=Y54} -> -7.4659091 | M16: 1 | N16: {=C16+E16+G16+I16+K16+M16} -> 22.5 | P16: 4th | Q16: 5 | T16: Lindsay | W16: - | Z16: -
A17: Lance | B17: {=M29} -> 36.443182 | C17: 7 | D17: {=Y29} -> 53.443182 | E17: 2 | F17: {=M42} -> 31.443182 | G17: 7 | H17: {=Y42} -> 50.443182 | I17: 1.5 | J17: 34.443182 | K17: 3 | L17: {=Y55} -> 35.443182 | M17: 4.5 | N17: {=C17+E17+G17+I17+K17+M17} -> 25 | P17: 5th | Q17: 4 | T17: Lance | W17: - | Y17: 17.7 | Z17: -
A18: Shea | B18: {=M30} -> -7.375 | C18: 1 | D18: {=Y30} -> -7.375 | E18: 1 | F18: {=M43} -> 36.625 | G18: 4 | H18: {=Y43} -> 38.625 | I18: 6 | J18: 31.625 | K18: 4 | L18: {=Y56} -> 37.625 | M18: 2 | N18: {=C18+E18+G18+I18+K18+M18} -> 18 | P18: 6th | Q18: 3 | T18: Shea | W18: 11.9 | Y18: 6.1 | Z18: 12.9
A19: Tim | B19: {=M31} -> 35.240385 | C19: 8 | D19: {=Y31} -> 36.240385 | E19: 4.5 | F19: {=M44} -> 40.240385 | G19: 2 | H19: {=Y44} -> 37.240385 | I19: 8 | J19: 36.240385 | K19: 2 | L19: {=Y57} -> 31.240385 | M19: 7 | N19: {=C19+E19+G19+I19+K19+M19} -> 31.5 | P19: 7th | Q19: 2 | T19: Tim | W19: - | Y19: - | Z19: -
A20: Sonat | B20: {=M32} -> 38.767857 | C20: 5 | D20: {=Y32} -> 34.767857 | E20: 6 | F20: {=M45} -> 38.767857 | G20: 3 | H20: {=Y45} -> 41.767857 | I20: 4 | J20: 26.767857 | K20: 7.5 | L20: {=Y58} -> 31.767857 | M20: 6 | N20: {=C20+E20+G20+I20+K20+M20} -> 31.5 | P20: 8th | Q20: 1 | T20: Sonat | W20: 13.2 | Y20: 0,9 | Z20: -
A21: Jeremy | B21: {=M33} -> 47.041667 | C21: 3 | D21: {=Y33} -> 27.041667 | E21: 8 | F21: {=M46} -> 30.041667 | G21: 8 | H21: {=Y46} -> 38.041667 | I21: 7 | J21: 27.041667 | K21: 7.5 | L21: {=Y59} -> 28.041667 | M21: 8 | N21: {=C21+E21+G21+I21+K21+M21} -> 41.5 | T21: Jeremy | W21: - | Y21: - | Z21: -
A23: Mattaponi Springs | B23: 1 | C23: 2 | D23: 3 | E23: 4 | F23: 5 | G23: 6 | H23: 7 | I23: 8 | J23: 9 | K23: Total | L23: Handicap | M23: Score | N23: 10 | O23: 11 | P23: 12 | Q23: 13 | R23: 14 | S23: 15 | T23: 16 | U23: 17 | V23: 18 | W23: Total | X23: Handicap | Y23: Score
A24: Par | B24: 4 | C24: 5 | D24: 3 | E24: 4 | F24: 4 | G24: 5 | H24: 3 | I24: 4 | J24: 4 | K24: {=SUM(B24:J24)} -> 36 | N24: 4 | O24: 4 | P24: 5 | Q24: 4 | R24: 3 | S24: 4 | T24: 5 | U24: 3 | V24: 4 | W24: {=SUM(N24:V24)} -> 36
A25: Player
A26: Cody | B26: 12 | C26: 9 | D26: 3 | E26: 15 | F26: 6 | G26: 9 | H26: 6 | I26: 6 | J26: 8 | K26: {=SUM(B26:J26)} -> 74 | L26: 24.291667 | M26: {=K26-L26} -> 49.708333 | N26: 6 | O26: 7 | P26: 12 | Q26: 6 | R26: 4 | S26: 7 | T26: 9 | U26: 5 | V26: 7 | W26: {=SUM(N26:V26)} -> 63 | X26: 24.291667 | Y26: {=W26-X26} -> 38.708333
A27: Jordan | B27: 6 | C27: 7 | D27: 4 | E27: 7 | F27: 7 | G27: 8 | H27: 4 | I27: 8 | J27: 5 | K27: {=SUM(B27:J27)} -> 56 | L27: 12.675 | M27: {=K27-L27} -> 43.325 | N27: 4 | O27: 6 | P27: 6 | Q27: 4 | R27: 3 | S27: 5 | T27: 6 | U27: 5 | V27: 5 | W27: {=SUM(N27:V27)} -> 44 | X27: 12.675 | Y27: {=W27-X27} -> 31.325
A28: Lindsay | B28: 8 | C28: 7 | D28: 2 | E28: 6 | F28: 4 | G28: 5 | H28: 3 | I28: 4 | J28: 5 | K28: {=SUM(B28:J28)} -> 44 | L28: 7.4659091 | M28: {=K28-L28} -> 36.534091 | N28: 7 | O28: 5 | P28: 5 | Q28: 4 | R28: 4 | S28: 4 | T28: 5 | U28: 4 | V28: 5 | W28: {=SUM(N28:V28)} -> 43 | X28: 7.4659091 | Y28: {=W28-X28} -> 35.534091
A29: Lance | B29: 8 | C29: 9 | D29: 5 | E29: 6 | F29: 5 | G29: 8 | H29: 5 | I29: 7 | J29: 5 | K29: {=SUM(B29:J29)} -> 58 | L29: 21.556818 | M29: {=K29-L29} -> 36.443182 | N29: 7 | O29: 8 | P29: 10 | Q29: 12 | R29: 6 | S29: 8 | T29: 12 | U29: 5 | V29: 7 | W29: {=SUM(N29:V29)} -> 75 | X29: 21.556818 | Y29: {=W29-X29} -> 53.443182
A30: Shea | K30: {=SUM(B30:J30)} -> 0 | L30: 7.375 | M30: {=K30-L30} -> -7.375 | W30: {=SUM(N30:V30)} -> 0 | X30: 7.375 | Y30: {=W30-X30} -> -7.375
A31: Tim | B31: 4 | C31: 5 | D31: 3 | E31: 7 | F31: 4 | G31: 6 | H31: 5 | I31: 4 | J31: 5 | K31: {=SUM(B31:J31)} -> 43 | L31: 7.7596154 | M31: {=K31-L31} -> 35.240385 | N31: 4 | O31: 7 | P31: 6 | Q31: 4 | R31: 5 | S31: 4 | T31: 6 | U31: 3 | V31: 5 | W31: {=SUM(N31:V31)} -> 44 | X31: 7.7596154 | Y31: {=W31-X31} -> 36.240385
A32: Sonat | B32: 8 | C32: 8 | D32: 4 | E32: 5 | F32: 4 | G32: 6 | H32: 4 | I32: 4 | J32: 6 | K32: {=SUM(B32:J32)} -> 49 | L32: 10.232143 | M32: {=K32-L32} -> 38.767857 | N32: 5 | O32: 5 | P32: 7 | Q32: 4 | R32: 4 | S32: 4 | T32: 6 | U32: 4 | V32: 6 | W32: {=SUM(N32:V32)} -> 45 | X32: 10.232143 | Y32: {=W32-X32} -> 34.767857
A33: Jeremy | B33: 11 | C33: 9 | D33: 5 | E33: 9 | F33: 5 | G33: 8 | H33: 5 | I33: 7 | J33: 13 | K33: {=SUM(B33:J33)} -> 72 | L33: 24.958333 | M33: {=K33-L33} -> 47.041667 | N33: 6 | O33: 8 | P33: 6 | Q33: 6 | R33: 4 | S33: 5 | T33: 8 | U33: 4 | V33: 5 | W33: {=SUM(N33:V33)} -> 52 | X33: 24.958333 | Y33: {=W33-X33} -> 27.041667
D34: 115 yrd | H34: 158 yrd | R34: 189 yrd | U34: 136 yrd
A36: Augusta | B36: 1 | C36: 2 | D36: 3 | E36: 4 | F36: 5 | G36: 6 | H36: 7 | I36: 8 | J36: 9 | K36: Total | L36: Handicap | M36: Score | N36: 10 | O36: 11 | P36: 12 | Q36: 13 | R36: 14 | S36: 15 | T36: 16 | U36: 17 | V36: 18 | W36: Total | X36: Handicap | Y36: Score
A37: Par | B37: 4 | C37: 5 | D37: 4 | E37: 3 | F37: 4 | G37: 3 | H37: 4 | I37: 5 | J37: 4 | K37: {=SUM(B37:J37)} -> 36 | N37: 4 | O37: 4 | P37: 3 | Q37: 5 | R37: 4 | S37: 5 | T37: 3 | U37: 4 | V37: 4 | W37: {=SUM(N37:V37)} -> 36
A38: Player
A39: Cody | B39: 6 | C39: 8 | D39: 6 | E39: 5 | F39: 6 | G39: 4 | H39: 9 | I39: 8 | J39: 7 | K39: {=SUM(B39:J39)} -> 59 | L39: 24.291667 | M39: {=K39-L39} -> 34.708333 | N39: 7 | O39: 8 | P39: 7 | Q39: 14 | R39: 7 | S39: 8 | T39: 5 | U39: 6 | V39: 10 | W39: {=SUM(N39:V39)} -> 72 | X39: 24.291667 | Y39: {=W39-X39} -> 47.708333
A40: Jordan | B40: 7 | C40: 7 | D40: 6 | E40: 4 | F40: 11 | G40: 6 | H40: 6 | I40: 6 | J40: 6 | K40: {=SUM(B40:J40)} -> 59 | L40: 12.675 | M40: {=K40-L40} -> 46.325 | N40: 8 | O40: 7 | P40: 4 | Q40: 9 | R40: 8 | S40: 8 | T40: 4 | U40: 6 | V40: 9 | W40: {=SUM(N40:V40)} -> 63 | X40: 12.675 | Y40: {=W40-X40} -> 50.325
A41: Lindsay | B41: 6 | C41: 5 | D41: 4 | E41: 4 | F41: 5 | G41: 4 | H41: 5 | I41: 6 | J41: 4 | K41: {=SUM(B41:J41)} -> 43 | L41: 7.4659091 | M41: {=K41-L41} -> 35.534091 | N41: 7 | O41: 4 | P41: 4 | Q41: 7 | R41: 5 | S41: 5 | T41: 4 | U41: 6 | V41: 6 | W41: {=SUM(N41:V41)} -> 48 | X41: 7.4659091 | Y41: {=W41-X41} -> 40.534091
A42: Lance | B42: 7 | C42: 6 | D42: 5 | E42: 4 | F42: 7 | G42: 3 | H42: 7 | I42: 6 | J42: 8 | K42: {=SUM(B42:J42)} -> 53 | L42: 21.556818 | M42: {=K42-L42} -> 31.443182 | N42: 9 | O42: 5 | P42: 12 | Q42: 11 | R42: 6 | S42: 7 | T42: 6 | U42: 6 | V42: 10 | W42: {=SUM(N42:V42)} -> 72 | X42: 21.556818 | Y42: {=W42-X42} -> 50.443182
A43: Shea | B43: 4 | C43: 6 | D43: 4 | E43: 4 | F43: 7 | G43: 7 | H43: 4 | I43: 4 | J43: 4 | K43: {=SUM(B43:J43)} -> 44 | L43: 7.375 | M43: {=K43-L43} -> 36.625 | N43: 6 | O43: 5 | P43: 3 | Q43: 5 | R43: 9 | S43: 5 | T43: 4 | U43: 4 | V43: 5 | W43: {=SUM(N43:V43)} -> 46 | X43: 7.375 | Y43: {=W43-X43} -> 38.625
A44: Tim | B44: 5 | C44: 6 | D44: 5 | E44: 6 | F44: 7 | G44: 5 | H44: 4 | I44: 4 | J44: 6 | K44: {=SUM(B44:J44)} -> 48 | L44: 7.7596154 | M44: {=K44-L44} -> 40.240385 | N44: 5 | O44: 4 | P44: 3 | Q44: 8 | R44: 4 | S44: 5 | T44: 6 | U44: 5 | V44: 5 | W44: {=SUM(N44:V44)} -> 45 | X44: 7.7596154 | Y44: {=W44-X44} -> 37.240385
A45: Sonat | B45: 4 | C45: 6 | D45: 6 | E45: 5 | F45: 5 | G45: 4 | H45: 6 | I45: 6 | J45: 7 | K45: {=SUM(B45:J45)} -> 49 | L45: 10.232143 | M45: {=K45-L45} -> 38.767857 | N45: 5 | O45: 5 | P45: 5 | Q45: 6 | R45: 6 | S45: 8 | T45: 5 | U45: 5 | V45: 7 | W45: {=SUM(N45:V45)} -> 52 | X45: 10.232143 | Y45: {=W45-X45} -> 41.767857
A46: Jeremy | B46: 9 | C46: 6 | D46: 5 | E46: 6 | F46: 6 | G46: 4 | H46: 6 | I46: 7 | J46: 6 | K46: {=SUM(B46:J46)} -> 55 | L46: 24.958333 | M46: {=K46-L46} -> 30.041667 | N46: 8 | O46: 5 | P46: 7 | Q46: 7 | R46: 6 | S46: 12 | T46: 5 | U46: 6 | V46: 7 | W46: {=SUM(N46:V46)} -> 63 | X46: 24.958333 | Y46: {=W46-X46} -> 38.041667
E47: 226 yrd | G47: 173 yrd | P47: 144 yrd | T47: 155 yrd
A49: Cabot Cliff | B49: 1 | C49: 2 | D49: 3 | E49: 4 | F49: 5 | G49: 6 | H49: 7 | I49: 8 | J49: 9 | K49: Total | L49: Handicap | M49: Score | N49: 10 | O49: 11 | P49: 12 | Q49: 13 | R49: 14 | S49: 15 | T49: 16 | U49: 17 | V49: 18 | W49: Total | X49: Handicap | Y49: Score
A50: Par | B50: 5 | C50: 4 | D50: 4 | E50: 3 | F50: 4 | G50: 3 | H50: 5 | I50: 5 | J50: 3 | K50: {=SUM(B50:J50)} -> 36 | N50: 5 | O50: 4 | P50: 3 | Q50: 4 | R50: 3 | S50: 5 | T50: 3 | U50: 4 | V50: 5 | W50: {=SUM(N50:V50)} -> 36
A51: Player
A52: Cody | B52: 9 | C52: 7 | D52: 5 | E52: 4 | F52: 5 | G52: 5 | H52: 7 | I52: 8 | J52: 4 | K52: {=SUM(B52:J52)} -> 54 | L52: 24.291667 | M52: {=K52-L52} -> 29.708333 | N52: 6 | O52: 6 | P52: 4 | Q52: 6 | R52: 5 | S52: 7 | T52: 6 | U52: 9 | V52: 10 | W52: {=SUM(N52:V52)} -> 59 | X52: 24.291667 | Y52: {=W52-X52} -> 34.708333
A53: Jordan | B53: 6 | C53: 7 | D53: 5 | E53: 5 | F53: 3 | G53: 4 | H53: 6 | I53: 5 | J53: 3 | K53: {=SUM(B53:J53)} -> 44 | L53: 12.675 | M53: {=K53-L53} -> 31.325 | N53: 7 | O53: 5 | P53: 5 | Q53: 5 | R53: 3 | S53: 6 | T53: 4 | U53: 7 | V53: 7 | W53: {=SUM(N53:V53)} -> 49 | X53: 12.675 | Y53: {=W53-X53} -> 36.325
A54: Lindsay | K54: {=SUM(B54:J54)} -> 0 | L54: 7.4659091 | M54: {=K54-L54} -> -7.4659091 | W54: {=SUM(N54:V54)} -> 0 | X54: 7.4659091 | Y54: {=W54-X54} -> -7.4659091
...

Sheet Handicap Summary
A1: Tournament 1
A2: Player | B2: Week 1 | C2: Week 2 | D2: 2 Wk Ave | E2: Par 36
A3: Cody | B3: {='Wk1and2'!K5} -> 63 | C3: {='Wk1and2'!V5} -> 60 | D3: {=(B3+C3)/2} -> 61.5 | E3: {=D3-36} -> 25.5
A4: Jordan | B4: {='Wk1and2'!K7} -> 43 | C4: {='Wk1and2'!V7} -> 50 | D4: {=(B4+C4)/2} -> 46.5 | E4: {=D4-36} -> 10.5
A5: Lindsay | B5: {='Wk1and2'!K9} -> 42 | C5: {='Wk1and2'!V9} -> 44 | D5: {=(B5+C5)/2} -> 43 | E5: {=D5-36} -> 7
A6: Lance | B6: {='Wk1and2'!K11} -> 59 | C6: {='Wk1and2'!V11} -> 57 | D6: {=(B6+C6)/2} -> 58 | E6: {=D6-36} -> 22
A7: Shea | B7: {='Wk1and2'!K13} -> 52 | C7: {='Wk1and2'!V13} -> 45 | D7: {=(B7+C7)/2} -> 48.5 | E7: {=D7-36} -> 12.5
A8: Tim | B8: {='Wk1and2'!K15} -> 45 | C8: {='Wk1and2'!V15} -> 51 | D8: {=(B8+C8)/2} -> 48 | E8: {=D8-36} -> 12
A9: Sonat | B9: {='Wk1and2'!K17} -> 47 | C9: {='Wk1and2'!V17} -> 50 | D9: {=(B9+C9)/2} -> 48.5 | E9: {=D9-36} -> 12.5
A10: Jeremy | B10: 59 | C10: {='Wk1and2'!V19} -> 59 | D10: {=(B10+C10)/2} -> 59 | E10: {=D10-36} -> 23

Sheet Wk1and2
A1: Paynes Valley Wk 1 | B1: 1 | C1: 2 | D1: 3 | E1: 4 | F1: 5 | G1: 6 | H1: 7 | I1: 8 | J1: 9 | K1: Total | L1: Handicap | M1: 10 | N1: 11 | O1: 12 | P1: 13 | Q1: 14 | R1: 15 | S1: 16 | T1: 17 | U1: 18 | V1: Total | W1: Handicap
A2: Par | B2: 4 | C2: 3 | D2: 4 | E2: 5 | F2: 3 | G2: 4 | H2: 4 | I2: 5 | J2: 4 | K2: {=SUM(B2:J2)} -> 36 | M2: 3 | N2: 4 | O2: 4 | P2: 5 | Q2: 4 | R2: 4 | S2: 3 | T2: 4 | U2: 5 | V2: {=SUM(M2:U2)} -> 36
A3: Player
A4: Cody | B4: 7 | C4: 4 | D4: 7 | E4: 9 | F4: 7 | G4: 8 | H4: 8 | I4: 8 | J4: 6 | K4: {=SUM(B4:J4)} -> 64 | M4: 5 | N4: 6 | O4: 7 | P4: 9 | Q4: 7 | R4: 9 | S4: 4 | T4: 6 | U4: 8 | V4: {=SUM(M4:U4)} -> 61
A5: Adjusted HC | B5: {=IF(B4>B2*2,B2*2,B4)} -> 7 | C5: {=IF(C4>C2*2,C2*2,C4)} -> 4 | D5: {=IF(D4>D2*2,D2*2,D4)} -> 7 | E5: {=IF(E4>E2*2,E2*2,E4)} -> 9 | F5: {=IF(F4>F2*2,F2*2,F4)} -> 6 | G5: {=IF(G4>G2*2,G2*2,G4)} -> 8 | H5: {=IF(H4>H2*2,H2*2,H4)} -> 8 | I5: {=IF(I4>I2*2,I2*2,I4)} -> 8 | J5: {=IF(J4>J2*2,J2*2,J4)} -> 6 | K5: {=SUM(B5:J5)} -> 63 | L5: {=K5-K2} -> 27 | M5: {=IF(M4>M2*2,M2*2,M4)} -> 5 | N5: {=IF(N4>N2*2,N2*2,N4)} -> 6 | O5: {=IF(O4>O2*2,O2*2,O4)} -> 7 | P5: {=IF(P4>P2*2,P2*2,P4)} -> 9 | Q5: {=IF(Q4>Q2*2,Q2*2,Q4)} -> 7 | R5: {=IF(R4>R2*2,R2*2,R4)} -> 8 | S5: {=IF(S4>S2*2,S2*2,S4)} -> 4 | T5: {=IF(T4>T2*2,T2*2,T4)} -> 6 | U5: {=IF(U4>U2*2,U2*2,U4)} -> 8 | V5: {=SUM(M5:U5)} -> 60 | W5: {=V5-V2} -> 24
A6: Jordan | B6: 5 | C6: 2 | D6: 5 | E6: 6 | F6: 3 | G6: 5 | H6: 4 | I6: 7 | J6: 6 | K6: {=SUM(B6:J6)} -> 43 | M6: 4 | N6: 5 | O6: 6 | P6: 5 | Q6: 6 | R6: 6 | S6: 6 | T6: 6 | U6: 6 | V6: {=SUM(M6:U6)} -> 50
A7: Adjusted HC | B7: {=IF(B6>B2*2,B2*2,B6)} -> 5 | C7: {=IF(C6>C2*2,C2*2,C6)} -> 2 | D7: {=IF(D6>D2*2,D2*2,D6)} -> 5 | E7: {=IF(E6>E2*2,E2*2,E6)} -> 6 | F7: {=IF(F6>F2*2,F2*2,F6)} -> 3 | G7: {=IF(G6>G2*2,G2*2,G6)} -> 5 | H7: {=IF(H6>H2*2,H2*2,H6)} -> 4 | I7: {=IF(I6>I2*2,I2*2,I6)} -> 7 | J7: {=IF(J6>J2*2,J2*2,J6)} -> 6 | K7: {=SUM(B7:J7)} -> 43 | L7: {=K7-K2} -> 7 | M7: {=IF(M6>M2*2,M2*2,M6)} -> 4 | N7: {=IF(N6>N2*2,N2*2,N6)} -> 5 | O7: {=IF(O6>O2*2,O2*2,O6)} -> 6 | P7: {=IF(P6>P2*2,P2*2,P6)} -> 5 | Q7: {=IF(Q6>Q2*2,Q2*2,Q6)} -> 6 | R7: {=IF(R6>R2*2,R2*2,R6)} -> 6 | S7: {=IF(S6>S2*2,S2*2,S6)} -> 6 | T7: {=IF(T6>T2*2,T2*2,T6)} -> 6 | U7: {=IF(U6>U2*2,U2*2,U6)} -> 6 | V7: {=SUM(M7:U7)} -> 50 | W7: {=V7-V2} -> 14
A8: Lindsay | B8: 5 | C8: 4 | D8: 3 | E8: 5 | F8: 3 | G8: 6 | H8: 4 | I8: 7 | J8: 5 | K8: {=SUM(B8:J8)} -> 42 | M8: 5 | N8: 5 | O8: 4 | P8: 6 | Q8: 5 | R8: 5 | S8: 3 | T8: 5 | U8: 6 | V8: {=SUM(M8:U8)} -> 44
A9: Adjusted HC | B9: {=IF(B8>B2*2,B2*2,B8)} -> 5 | C9: {=IF(C8>C2*2,C2*2,C8)} -> 4 | D9: {=IF(D8>D2*2,D2*2,D8)} -> 3 | E9: {=IF(E8>E2*2,E2*2,E8)} -> 5 | F9: {=IF(F8>F2*2,F2*2,F8)} -> 3 | G9: {=IF(G8>G2*2,G2*2,G8)} -> 6 | H9: {=IF(H8>H2*2,H2*2,H8)} -> 4 | I9: {=IF(I8>I2*2,I2*2,I8)} -> 7 | J9: {=IF(J8>J2*2,J2*2,J8)} -> 5 | K9: {=SUM(B9:J9)} -> 42 | L9: {=K9-K2} -> 6 | M9: {=IF(M8>M2*2,M2*2,M8)} -> 5 | N9: {=IF(N8>N2*2,N2*2,N8)} -> 5 | O9: {=IF(O8>O2*2,O2*2,O8)} -> 4 | P9: {=IF(P8>P2*2,P2*2,P8)} -> 6 | Q9: {=IF(Q8>Q2*2,Q2*2,Q8)} -> 5 | R9: {=IF(R8>R2*2,R2*2,R8)} -> 5 | S9: {=IF(S8>S2*2,S2*2,S8)} -> 3 | T9: {=IF(T8>T2*2,T2*2,T8)} -> 5 | U9: {=IF(U8>U2*2,U2*2,U8)} -> 6 | V9: {=SUM(M9:U9)} -> 44 | W9: {=V9-V2} -> 8
A10: Lance | B10: 8 | C10: 4 | D10: 5 | E10: 10 | F10: 7 | G10: 5 | H10: 9 | I10: 5 | J10: 9 | K10: {=SUM(B10:J10)} -> 62 | M10: 7 | N10: 6 | O10: 6 | P10: 6 | Q10: 7 | R10: 8 | S10: 4 | T10: 6 | U10: 8 | V10: {=SUM(M10:U10)} -> 58
A11: Adjusted HC | B11: {=IF(B10>B2*2,B2*2,B10)} -> 8 | C11: {=IF(C10>C2*2,C2*2,C10)} -> 4 | D11: {=IF(D10>D2*2,D2*2,D10)} -> 5 | E11: {=IF(E10>E2*2,E2*2,E10)} -> 10 | F11: {=IF(F10>F2*2,F2*2,F10)} -> 6 | G11: {=IF(G10>G2*2,G2*2,G10)} -> 5 | H11: {=IF(H10>H2*2,H2*2,H10)} -> 8 | I11: {=IF(I10>I2*2,I2*2,I10)} -> 5 | J11: {=IF(J10>J2*2,J2*2,J10)} -> 8 | K11: {=SUM(B11:J11)} -> 59 | L11: {=K11-K2} -> 23 | M11: {=IF(M10>M2*2,M2*2,M10)} -> 6 | N11: {=IF(N10>N2*2,N2*2,N10)} -> 6 | O11: {=IF(O10>O2*2,O2*2,O10)} -> 6 | P11: {=IF(P10>P2*2,P2*2,P10)} -> 6 | Q11: {=IF(Q10>Q2*2,Q2*2,Q10)} -> 7 | R11: {=IF(R10>R2*2,R2*2,R10)} -> 8 | S11: {=IF(S10>S2*2,S2*2,S10)} -> 4 | T11: {=IF(T10>T2*2,T2*2,T10)} -> 6 | U11: {=IF(U10>U2*2,U2*2,U10)} -> 8 | V11: {=SUM(M11:U11)} -> 57 | W11: {=V11-V2} -> 21
A12: Shea | B12: 6 | C12: 6 | D12: 4 | E12: 6 | F12: 5 | G12: 7 | H12: 5 | I12: 7 | J12: 6 | K12: {=SUM(B12:J12)} -> 52 | M12: 4 | N12: 6 | O12: 6 | P12: 5 | Q12: 5 | R12: 5 | S12: 4 | T12: 5 | U12: 5 | V12: {=SUM(M12:U12)} -> 45
A13: Adjusted HC | B13: {=IF(B12>B2*2,B2*2,B12)} -> 6 | C13: {=IF(C12>C2*2,C2*2,C12)} -> 6 | D13: {=IF(D12>D2*2,D2*2,D12)} -> 4 | E13: {=IF(E12>E2*2,E2*2,E12)} -> 6 | F13: {=IF(F12>F2*2,F2*2,F12)} -> 5 | G13: {=IF(G12>G2*2,G2*2,G12)} -> 7 | H13: {=IF(H12>H2*2,H2*2,H12)} -> 5 | I13: {=IF(I12>I2*2,I2*2,I12)} -> 7 | J13: {=IF(J12>J2*2,J2*2,J12)} -> 6 | K13: {=SUM(B13:J13)} -> 52 | L13: {=K13-K2} -> 16 | M13: {=IF(M12>M2*2,M2*2,M12)} -> 4 | N13: {=IF(N12>N2*2,N2*2,N12)} -> 6 | O13: {=IF(O12>O2*2,O2*2,O12)} -> 6 | P13: {=IF(P12>P2*2,P2*2,P12)} -> 5 | Q13: {=IF(Q12>Q2*2,Q2*2,Q12)} -> 5 | R13: {=IF(R12>R2*2,R2*2,R12)} -> 5 | S13: {=IF(S12>S2*2,S2*2,S12)} -> 4 | T13: {=IF(T12>T2*2,T2*2,T12)} -> 5 | U13: {=IF(U12>U2*2,U2*2,U12)} -> 5 | V13: {=SUM(M13:U13)} -> 45 | W13: {=V13-V2} -> 9
A14: Tim | B14: 5 | C14: 4 | D14: 4 | E14: 6 | F14: 3 | G14: 5 | H14: 6 | I14: 6 | J14: 6 | K14: {=SUM(B14:J14)} -> 45 | M14: 4 | N14: 6 | O14: 5 | P14: 6 | Q14: 5 | R14: 5 | S14: 6 | T14: 7 | U14: 7 | V14: {=SUM(M14:U14)} -> 51
A15: Adjusted HC | B15: {=IF(B14>B2*2,B2*2,B14)} -> 5 | C15: {=IF(C14>C2*2,C2*2,C14)} -> 4 | D15: {=IF(D14>D2*2,D2*2,D14)} -> 4 | E15: {=IF(E14>E2*2,E2*2,E14)} -> 6 | F15: {=IF(F14>F2*2,F2*2,F14)} -> 3 | G15: {=IF(G14>G2*2,G2*2,G14)} -> 5 | H15: {=IF(H14>H2*2,H2*2,H14)} -> 6 | I15: {=IF(I14>I2*2,I2*2,I14)} -> 6 | J15: {=IF(J14>J2*2,J2*2,J14)} -> 6 | K15: {=SUM(B15:J15)} -> 45 | L15: {=K15-K2} -> 9 | M15: {=IF(M14>M2*2,M2*2,M14)} -> 4 | N15: {=IF(N14>N2*2,N2*2,N14)} -> 6 | O15: {=IF(O14>O2*2,O2*2,O14)} -> 5 | P15: {=IF(P14>P2*2,P2*2,P14)} -> 6 | Q15: {=IF(Q14>Q2*2,Q2*2,Q14)} -> 5 | R15: {=IF(R14>R2*2,R2*2,R14)} -> 5 | S15: {=IF(S14>S2*2,S2*2,S14)} -> 6 | T15: {=IF(T14>T2*2,T2*2,T14)} -> 7 | U15: {=IF(U14>U2*2,U2*2,U14)} -> 7 | V15: {=SUM(M15:U15)} -> 51 | W15: {=V15-V2} -> 15
A16: Sonat | B16: 5 | C16: 4 | D16: 5 | E16: 5 | F16: 4 | G16: 6 | H16: 4 | I16: 8 | J16: 6 | K16: {=SUM(B16:J16)} -> 47 | M16: 5 | N16: 5 | O16: 5 | P16: 7 | Q16: 5 | R16: 6 | S16: 5 | T16: 6 | U16: 6 | V16: {=SUM(M16:U16)} -> 50
A17: Adjusted HC | B17: {=IF(B16>B2*2,B2*2,B16)} -> 5 | C17: {=IF(C16>C2*2,C2*2,C16)} -> 4 | D17: {=IF(D16>D2*2,D2*2,D16)} -> 5 | E17: {=IF(E16>E2*2,E2*2,E16)} -> 5 | F17: {=IF(F16>F2*2,F2*2,F16)} -> 4 | G17: {=IF(G16>G2*2,G2*2,G16)} -> 6 | H17: {=IF(H16>H2*2,H2*2,H16)} -> 4 | I17: {=IF(I16>I2*2,I2*2,I16)} -> 8 | J17: {=IF(J16>J2*2,J2*2,J16)} -> 6 | K17: {=SUM(B17:J17)} -> 47 | L17: {=K17-K2} -> 11 | M17: {=IF(M16>M2*2,M2*2,M16)} -> 5 | N17: {=IF(N16>N2*2,N2*2,N16)} -> 5 | O17: {=IF(O16>O2*2,O2*2,O16)} -> 5 | P17: {=IF(P16>P2*2,P2*2,P16)} -> 7 | Q17: {=IF(Q16>Q2*2,Q2*2,Q16)} -> 5 | R17: {=IF(R16>R2*2,R2*2,R16)} -> 6 | S17: {=IF(S16>S2*2,S2*2,S16)} -> 5 | T17: {=IF(T16>T2*2,T2*2,T16)} -> 6 | U17: {=IF(U16>U2*2,U2*2,U16)} -> 6 | V17: {=SUM(M17:U17)} -> 50 | W17: {=V17-V2} -> 14
A18: Jeremy | K18: {=SUM(B18:J18)} -> 0 | M18: 4 | N18: 7 | O18: 6 | P18: 7 | Q18: 7 | R18: 8 | S18: 4 | T18: 6 | U18: 20 | V18: {=SUM(M18:U18)} -> 69
A19: Adjusted HC | B19: {=IF(B18>B2*2,B2*2,B18)} -> 0 | C19: {=IF(C18>C2*2,C2*2,C18)} -> 0 | D19: {=IF(D18>D2*2,D2*2,D18)} -> 0 | E19: {=IF(E18>E2*2,E2*2,E18)} -> 0 | F19: {=IF(F18>F2*2,F2*2,F18)} -> 0 | G19: {=IF(G18>G2*2,G2*2,G18)} -> 0 | H19: {=IF(H18>H2*2,H2*2,H18)} -> 0 | I19: {=IF(I18>I2*2,I2*2,I18)} -> 0 | J19: {=IF(J18>J2*2,J2*2,J18)} -> 0 | K19: {=SUM(B19:J19)} -> 0 | L19: 59 | M19: {=IF(M18>M2*2,M2*2,M18)} -> 4 | N19: {=IF(N18>N2*2,N2*2,N18)} -> 7 | O19: {=IF(O18>O2*2,O2*2,O18)} -> 6 | P19: {=IF(P18>P2*2,P2*2,P18)} -> 7 | Q19: {=IF(Q18>Q2*2,Q2*2,Q18)} -> 7 | R19: {=IF(R18>R2*2,R2*2,R18)} -> 8 | S19: {=IF(S18>S2*2,S2*2,S18)} -> 4 | T19: {=IF(T18>T2*2,T2*2,T18)} -> 6 | U19: {=IF(U18>U2*2,U2*2,U18)} -> 10 | V19: {=SUM(M19:U19)} -> 59 | W19: {=V19-V2} -> 23

Sheet New Adj Cap
A1: Player | B1: Week 1 | C1: Week 2 | D1: Week 3 | E1: Week 4 | F1: Week 5 | G1: Week 6 | H1: Week 7 | I1: Week 8 | J1: total | K1: rounds | L1: Ave 9 score | M1: new cap | N1: old
A2: Cody | B2: {='Wk1and2'!K4} -> 64 | C2: {='Wk1and2'!V4} -> 61 | D2: 64 | E2: 0 | F2: 0 | G2: 60 | H2: 53 | I2: 56 | J2: {=SUM(B2:I2)} -> 358 | K2: 6 | L2: {=J2/K2} -> 59.666667 | M2: {=L2-E12} -> 24.041667 | N2: 25.5
A3: Jordan | B3: {='Wk1and2'!K6} -> 43 | C3: {='Wk1and2'!V6} -> 50 | D3: 43 | E3: 52 | F3: 49 | G3: 0 | H3: 58 | I3: 0 | J3: {=SUM(B3:I3)} -> 295 | K3: 6 | L3: {=J3/K3} -> 49.166667 | M3: {=L3-E12} -> 13.541667 | N3: 10.5
A4: Lindsay | B4: {='Wk1and2'!K8} -> 42 | C4: {='Wk1and2'!V8} -> 44 | D4: 43 | E4: 44 | F4: 39 | G4: 42 | H4: 41 | I4: 41 | J4: {=SUM(B4:I4)} -> 336 | K4: 8 | L4: {=J4/K4} -> 42 | M4: {=L4-E12} -> 6.375 | N4: 7
A5: Lance | B5: {='Wk1and2'!K10} -> 62 | C5: {='Wk1and2'!V10} -> 58 | D5: 62 | E5: 61 | F5: 60 | G5: 60 | H5: 56 | I5: 56 | J5: {=SUM(B5:I5)} -> 475 | K5: 8 | L5: {=J5/K5} -> 59.375 | M5: {=L5-E12} -> 23.75 | N5: 22
A6: Shea | B6: {='Wk1and2'!K12} -> 52 | C6: {='Wk1and2'!V12} -> 45 | D6: 44 | E6: 42 | F6: 38 | G6: 41 | H6: 0 | I6: 41 | J6: {=SUM(B6:I6)} -> 303 | K6: 7 | L6: {=J6/K6} -> 43.285714 | M6: {=L6-E12} -> 7.6607143 | N6: 12.5
A7: Tim | B7: {='Wk1and2'!K14} -> 45 | C7: {='Wk1and2'!V14} -> 51 | D7: 42 | E7: 45 | F7: 42 | G7: 46 | H7: 0 | I7: 44 | J7: {=SUM(B7:I7)} -> 315 | K7: 7 | L7: {=J7/K7} -> 45 | M7: {=L7-E12} -> 9.375 | N7: 12
A8: Sonat | B8: {='Wk1and2'!K16} -> 47 | C8: {='Wk1and2'!V16} -> 50 | D8: 49 | E8: 46 | F8: 39 | G8: 50 | H8: 43 | I8: 45 | J8: {=SUM(B8:I8)} -> 369 | K8: 8 | L8: {=J8/K8} -> 46.125 | M8: {=L8-E12} -> 10.5 | N8: 12.5
A9: Jeremy | B9: 59 | C9: {='Wk1and2'!V18} -> 69 | D9: 0 | E9: 62 | F9: 52 | G9: 61 | H9: 69 | I9: 54 | J9: {=SUM(B9:I9)} -> 426 | K9: 7 | L9: {=J9/K9} -> 60.857143 | M9: {=L9-E12} -> 25.232143 | N9: 23
D12: Ave 9 hole | E12: 35.625
A14: Player | B14: Week 1 | C14: Week 2 | D14: Week 3 | E14: Week 4 | F14: Week 5 | G14: Week 6 | H14: Week 7 | I14: Week 8 | J14: Week 9 | K14: Week 10 | L14: Week 11 | M14: Week 12 | N14: Week 13 | O14: Week 14 | P14: total | Q14: rounds | R14: ave 9 score | S14: new cap | T14: old
A15: Cody | B15: 64 | C15: 61 | D15: 64 | E15: 0 | F15: 0 | G15: 60 | H15: 53 | I15: 56 | J15: 64 | K15: 63 | L15: 55 | M15: 60 | N15: 58 | O15: 61 | P15: {=SUM(B15:O15)} -> 719 | Q15: 12 | R15: {=P15/Q15} -> 59.916667 | S15: 24.291667 | T15: 24
A16: Jordan | B16: 43 | C16: 50 | D16: 43 | E16: 52 | F16: 49 | G16: 0 | H16: 58 | I16: 0 | J16: 49 | K16: 41 | L16: 51 | M16: 47 | N16: 0 | O16: 0 | P16: {=SUM(B16:O16)} -> 483 | Q16: 10 | R16: {=P16/Q16} -> 48.3 | S16: 12.675 | T16: 14
A17: Lindsay | B17: 42 | C17: 44 | D17: 43 | E17: 44 | F17: 39 | G17: 42 | H17: 41 | I17: 41 | J17: 46 | K17: 0 | L17: 0 | M17: 47 | N17: 45 | O17: 0 | P17: {=SUM(B17:O17)} -> 474 | Q17: 11 | R17: {=P17/Q17} -> 43.090909 | S17: 7.4659091 | T17: 6
A18: Lance | B18: 62 | C18: 58 | D18: 62 | E18: 61 | F18: 60 | G18: 60 | H18: 56 | I18: 56 | J18: 51 | K18: 53 | L18: 0 | M18: 50 | N18: 0 | O18: 0 | P18: {=SUM(B18:O18)} -> 629 | Q18: 11 | R18: {=P18/Q18} -> 57.181818 | S18: 21.556818 | T18: 24
A19: Shea | B19: 52 | C19: 45 | D19: 44 | E19: 42 | F19: 38 | G19: 41 | H19: 0 | I19: 41 | J19: 45 | K19: 40 | L19: 38 | M19: 41 | N19: 45 | O19: 47 | P19: {=SUM(B19:O19)} -> 559 | Q19: 13 | R19: {=P19/Q19} -> 43 | S19: 7.375 | T19: 8
A20: Tim | B20: 45 | C20: 51 | D20: 42 | E20: 45 | F20: 42 | G20: 46 | H20: 0 | I20: 44 | J20: 38 | K20: 42 | L20: 41 | M20: 46 | N20: 40 | O20: 42 | P20: {=SUM(B20:O20)} -> 564 | Q20: 13 | R20: {=P20/Q20} -> 43.384615 | S20: 7.7596154 | T20: 9
A21: Sonat | B21: 47 | C21: 50 | D21: 49 | E21: 46 | F21: 39 | G21: 50 | H21: 43 | I21: 45 | J21: 47 | K21: 44 | L21: 42 | M21: 47 | N21: 40 | O21: 53 | P21: {=SUM(B21:O21)} -> 642 | Q21: 14 | R21: {=P21/Q21} -> 45.857143 | S21: 10.232143 | T21: 11
A22: Jeremy | B22: 59 | C22: 69 | D22: 0 | E22: 62 | F22: 52 | G22: 61 | H22: 69 | I22: 54 | J22: 0 | K22: 73 | L22: 54 | M22: 60 | N22: 55 | O22: 59 | P22: {=SUM(B22:O22)} -> 727 | Q22: 12 | R22: {=P22/Q22} -> 60.583333 | S22: 24.958333 | T22: 25
